Workbook

Sheet Grafik
A1: GRAFIK G01042 — WRZESIEŃ 2026
A3: Lp | B3: Pracownik | C3: 1 | D3: 2 | E3: 3 | F3: 4 | G3: 5 | H3: 6 | I3: 7 | J3: 8 | K3: 9 | L3: 10 | M3: 11 | N3: 12 | O3: 13 | P3: 14 | Q3: 15 | R3: 16 | S3: 17 | T3: 18 | U3: 19 | V3: 20 | W3: 21 | X3: 22 | Y3: 23 | Z3: 24 | AA3: 25 | AB3: 26 | AC3: 27 | AD3: 28 | AE3: 29 | AF3: 30 | AH3: Wypracowane h | AI3: Min h | AJ3: Max h | AK3: Status godzin | AL3: Kontrola 36 h
C4: Wt | D4: Śr | E4: Cz | F4: Pt | G4: Sb | H4: Nd | I4: Pn | J4: Wt | K4: Śr | L4: Cz | M4: Pt | N4: Sb | O4: Nd | P4: Pn | Q4: Wt | R4: Śr | S4: Cz | T4: Pt | U4: Sb | V4: Nd | W4: Pn | X4: Wt | Y4: Śr | Z4: Cz | AA4: Pt | AB4: Sb | AC4: Nd | AD4: Pn | AE4: Wt | AF4: Śr
A5: 1 | B5: Reszczyński Łukasz | C5: =IF(C29="","",C29) | D5: =IF(D29="","",D29) | E5: =IF(E29="","",E29) -> DN-K | F5: =IF(F29="","",F29) | G5: =IF(G29="","",G29) | H5: =IF(H29="","",H29) | I5: =IF(I29="","",I29) | J5: =IF(J29="","",J29) | ... AF5: =IF(AF29="","",AF29) | AH5: =COUNTIF(C5:AF5,"D-K")*12+COUNTIF(C5:AF5,"D-R")*12+COUNTIF(C5:AF5,"N-K")*12+COUNTIF(C5:AF5,"N-R")*12+COUNTIF(C5:AF5,"DN-K")*24+COUNTIF(C5:AF5,"DN-R")*24 -> 180 | AI5: 180 | AJ5: 240 | AK5: =IF(AH5<AI5,"PONIŻEJ MIN",IF(AH5>AJ5,"POWYŻEJ MAX","W NORMIE")) -> W NORMIE | AL5: =IF((IF(OR(AND(OR(C5="DN-K",C5="DN-R"),OR(D5="D-K",D5="D-R",D5="DN-K",D5="DN-R")),AND(OR(C5="N-K",C5="N-R"),OR(D5="DN-K",D5="DN-R"))),1,0) + IF(OR(AND(OR(D5="DN-K",D5="DN-R"),OR(E5="D-K",E5="D-R",E5="DN-K",E5="DN-R")),AND(OR(D5="N-K",D5="N-R"),OR(E5="DN-K",E5="DN-R"))),1,0) + IF(OR(AND(OR(E5="DN-K",E5="DN-R"),OR(F5="D-K",F5="D-R",F5="DN-K",F5="DN-R")),AND(OR(E5="N-K",E5="N-R"),OR(F5="DN-K",F5="DN-R"))),1,0) + IF(OR(AND(OR(F5="DN-K",F5="DN-R"),OR(G5="D-K",G5="D-R",G5="DN-K",G5="DN-R")),AND(OR(F5="N-K",F5="N-R"),OR(G5="DN-K",G5="DN-R"))),1,0) + IF(OR(AND(OR(G5="DN-K",G5="DN-R"),OR(H5="D-K",H5="D-R",H5="DN-K",H5="DN-R")),AND(OR(G5="N-K",G5="N-R"),OR(H5="DN-K",H5="DN-R"))),1,0) + IF(OR(AND(OR(H5="DN-K",H5="DN-R"),OR(I5="D-K",I5="D-R",I5="DN-K",I5="DN-R")),AND(OR(H5="N-K",H5="N-R"),OR(I5="DN-K",I5="DN-R"))),1,0) + IF(OR(AND(OR(I5="DN-K",I5="DN-R"),OR(J5="D-K",J5="D-R",J5="DN-K",J5="DN-R")),AND(OR(I5="N-K",I5="N-R"),OR(J5="DN-K",J5="DN-R"))),1,0) + IF(OR(AND(OR(J5="DN-K",J5="DN-R"),OR(K5="D-K",K5="D-R",K5="DN-K",K5="DN-R")),AND(OR(J5="N-K",J5="N-R"),OR(K5="DN-K",K5="DN-R"))),1,0) + IF(OR(AND(OR(K5="DN-K",K5="DN-R"),OR(L5="D-K",L5="D-R",L5="DN-K",L5="DN-R")),AND(OR(K5="N-K",K5="N-R"),OR(L5="DN-K",L5="DN-R"))),1,0) + IF(OR(AND(OR(L5="DN-K",L5="DN-R"),OR(M5="D-K",M5="D-R",M5="DN-K",M5="DN-R")),AND(OR(L5="N-K",L5="N-R"),OR(M5="DN-K",M5="DN-R"))),1,0) + IF(OR(AND(OR(M5="DN-K",M5="DN-R"),OR(N5="D-K",N5="D-R",N5="DN-K",N5="DN-R")),AND(OR(M5="N-K",M5="N-R"),OR(N5="DN-K",N5="DN-R"))),1,0) + IF(OR(AND(OR(N5="DN-K",N5="DN-R"),OR(O5="D-K",O5="D-R",O5="DN-K",O5="DN-R")),AND(OR(N5="N-K",N5="N-R"),OR(O5="DN-K",O5="DN-R"))),1,0) + IF(OR(AND(OR(O5="DN-K",O5="DN-R"),OR(P5="D-K",P5="D-R",P5="DN-K",P5="DN-R")),AND(OR(O5="N-K",O5="N-R"),OR(P5="DN-K",P5="DN-R"))),1,0) + IF(OR(AND(OR(P5="DN-K",P5="DN-R"),OR(Q5="D-K",Q5="D-R",Q5="DN-K",Q5="DN-R")),AND(OR(P5="N-K",P5="N-R"),OR(Q5="DN-K",Q5="DN-R"))),1,0) + IF(OR(AND(OR(Q5="DN-K",Q5="DN-R"),OR(R5="D-K",R5="D-R",R5="DN-K",R5="DN-R")),AND(OR(Q5="N-K",Q5="N-R"),OR(R5="DN-K",R5="DN-R"))),1,0) + IF(OR(AND(OR(R5="DN-K",R5="DN-R"),OR(S5="D-K",S5="D-R",S5="DN-K",S5="DN-R")),AND(OR(R5="N-K",R5="N-R"),OR(S5="DN-K",S5="DN-R"))),1,0) + IF(OR(AND(OR(S5="DN-K",S5="DN-R"),OR(T5="D-K",T5="D-R",T5="DN-K",T5="DN-R")),AND(OR(S5="N-K",S5="N-R"),OR(T5="DN-K",T5="DN-R"))),1,0) + IF(OR(AND(OR(T5="DN-K",T5="DN-R"),OR(U5="D-K",U5="D-R",U5="DN-K",U5="DN-R")),AND(OR(T5="N-K",T5="N-R"),OR(U5="DN-K",U5="DN-R"))),1,0) + IF(OR(AND(OR(U5="DN-K",U5="DN-R"),OR(V5="D-K",V5="D-R",V5="DN-K",V5="DN-R")),AND(OR(U5="N-K",U5="N-R"),OR(V5="DN-K",V5="DN-R"))),1,0) + IF(OR(AND(OR(V5="DN-K",V5="DN-R"),OR(W5="D-K",W5="D-R",W5="DN-K",W5="DN-R")),AND(OR(V5="N-K",V5="N-R"),OR(W5="DN-K",W5="DN-R"))),1,0) + IF(OR(AND(OR(W5="DN-K",W5="DN-R"),OR(X5="D-K",X5="D-R",X5="DN-K",X5="DN-R")),AND(OR(W5="N-K",W5="N-R"),OR(X5="DN-K",X5="DN-R"))),1,0) + IF(OR(AND(OR(X5="DN-K",X5="DN-R"),OR(Y5="D-K",Y5="D-R",Y5="DN-K",Y5="DN-R")),AND(OR(X5="N-K",X5="N-R"),OR(Y5="DN-K",Y5="DN-R"))),1,0) + IF(OR(AND(OR(Y5="DN-K",Y5="DN-R"),OR(Z5="D-K",Z5="D-R",Z5="DN-K",Z5="DN-R")),AND(OR(Y5="N-K",Y5="N-R"),OR(Z5="DN-K",Z5="DN-R"))),1,0) + IF(OR(AND(OR(Z5="DN-K",Z5="DN-R"),OR(AA5="D-K",AA5="D-R",AA5="DN-K",AA5="DN-R")),AND(OR(Z5="N-K",Z5="N-R"),OR(AA5="DN-K",AA5="DN-R"))),1,0) + IF(OR(AND(OR(AA5="DN-K",AA5="DN-R"),OR(AB5="D-K",AB5="D-R",AB5="DN-K",AB5="DN-R")),AND(OR(AA5="N-K",AA5="N-R"),OR(AB5="DN-K",AB5="DN-R"))),1,0) + IF(OR(AND(OR(AB5="DN-K",AB5="DN-R"),OR(AC5="D-K",AC5="D-R",AC5="DN-K",AC5="DN-R")),AND(OR(AB5="N-K",AB5="N-R"),OR(AC5="DN-K",AC5="DN-R"))),1,0) + IF(OR(AND(OR(AC5="DN-K",AC5="DN-R"),OR(AD5="D-K",AD5="D-R",AD5="DN-K",AD5="DN-R")),AND(OR(AC5="N-K",AC5="N-R"),OR(AD5="DN-K",AD5="DN-R"))),1,0) + IF(OR(AND(OR(AD5="DN-K",AD5="DN-R"),OR(AE5="D-K",AE5="D-R",AE5="DN-K",AE5="DN-R")),AND(OR(AD5="N-K",AD5="N-R"),OR(AE5="DN-K",AE5="DN-R"))),1,0) + IF(OR(AND(OR(AE5="DN-K",AE5="DN-R"),OR(AF5="D-K",AF5="D-R",AF5="DN-K",AF5="DN-R")),AND(OR(AE5="N-K",AE5="N-R"),OR(AF5="DN-K",AF5="DN-R"))),1,0))>0,"KONFLIKT 36H","OK") -> OK
A6: 2 | B6: Ceplin Waldemar | C6: =IF(C30="","",C30) | D6: =IF(D30="","",D30) | E6: =IF(E30="","",E30) | F6: =IF(F30="","",F30) -> DN-R | G6: =IF(G30="","",G30) -> N-R | H6: =IF(H30="","",H30) | I6: =IF(I30="","",I30) | J6: =IF(J30="","",J30) | ... AF6: =IF(AF30="","",AF30) | AH6: =COUNTIF(C6:AF6,"D-K")*12+COUNTIF(C6:AF6,"D-R")*12+COUNTIF(C6:AF6,"N-K")*12+COUNTIF(C6:AF6,"N-R")*12+COUNTIF(C6:AF6,"DN-K")*24+COUNTIF(C6:AF6,"DN-R")*24 -> 132 | AI6: 120 | AJ6: 180 | AK6: =IF(AH6<AI6,"PONIŻEJ MIN",IF(AH6>AJ6,"POWYŻEJ MAX","W NORMIE")) -> W NORMIE | AL6: =IF((IF(OR(AND(OR(C6="DN-K",C6="DN-R"),OR(D6="D-K",D6="D-R",D6="DN-K",D6="DN-R")),AND(OR(C6="N-K",C6="N-R"),OR(D6="DN-K",D6="DN-R"))),1,0) + IF(OR(AND(OR(D6="DN-K",D6="DN-R"),OR(E6="D-K",E6="D-R",E6="DN-K",E6="DN-R")),AND(OR(D6="N-K",D6="N-R"),OR(E6="DN-K",E6="DN-R"))),1,0) + IF(OR(AND(OR(E6="DN-K",E6="DN-R"),OR(F6="D-K",F6="D-R",F6="DN-K",F6="DN-R")),AND(OR(E6="N-K",E6="N-R"),OR(F6="DN-K",F6="DN-R"))),1,0) + IF(OR(AND(OR(F6="DN-K",F6="DN-R"),OR(G6="D-K",G6="D-R",G6="DN-K",G6="DN-R")),AND(OR(F6="N-K",F6="N-R"),OR(G6="DN-K",G6="DN-R"))),1,0) + IF(OR(AND(OR(G6="DN-K",G6="DN-R"),OR(H6="D-K",H6="D-R",H6="DN-K",H6="DN-R")),AND(OR(G6="N-K",G6="N-R"),OR(H6="DN-K",H6="DN-R"))),1,0) + IF(OR(AND(OR(H6="DN-K",H6="DN-R"),OR(I6="D-K",I6="D-R",I6="DN-K",I6="DN-R")),AND(OR(H6="N-K",H6="N-R"),OR(I6="DN-K",I6="DN-R"))),1,0) + IF(OR(AND(OR(I6="DN-K",I6="DN-R"),OR(J6="D-K",J6="D-R",J6="DN-K",J6="DN-R")),AND(OR(I6="N-K",I6="N-R"),OR(J6="DN-K",J6="DN-R"))),1,0) + IF(OR(AND(OR(J6="DN-K",J6="DN-R"),OR(K6="D-K",K6="D-R",K6="DN-K",K6="DN-R")),AND(OR(J6="N-K",J6="N-R"),OR(K6="DN-K",K6="DN-R"))),1,0) + IF(OR(AND(OR(K6="DN-K",K6="DN-R"),OR(L6="D-K",L6="D-R",L6="DN-K",L6="DN-R")),AND(OR(K6="N-K",K6="N-R"),OR(L6="DN-K",L6="DN-R"))),1,0) + IF(OR(AND(OR(L6="DN-K",L6="DN-R"),OR(M6="D-K",M6="D-R",M6="DN-K",M6="DN-R")),AND(OR(L6="N-K",L6="N-R"),OR(M6="DN-K",M6="DN-R"))),1,0) + IF(OR(AND(OR(M6="DN-K",M6="DN-R"),OR(N6="D-K",N6="D-R",N6="DN-K",N6="DN-R")),AND(OR(M6="N-K",M6="N-R"),OR(N6="DN-K",N6="DN-R"))),1,0) + IF(OR(AND(OR(N6="DN-K",N6="DN-R"),OR(O6="D-K",O6="D-R",O6="DN-K",O6="DN-R")),AND(OR(N6="N-K",N6="N-R"),OR(O6="DN-K",O6="DN-R"))),1,0) + IF(OR(AND(OR(O6="DN-K",O6="DN-R"),OR(P6="D-K",P6="D-R",P6="DN-K",P6="DN-R")),AND(OR(O6="N-K",O6="N-R"),OR(P6="DN-K",P6="DN-R"))),1,0) + IF(OR(AND(OR(P6="DN-K",P6="DN-R"),OR(Q6="D-K",Q6="D-R",Q6="DN-K",Q6="DN-R")),AND(OR(P6="N-K",P6="N-R"),OR(Q6="DN-K",Q6="DN-R"))),1,0) + IF(OR(AND(OR(Q6="DN-K",Q6="DN-R"),OR(R6="D-K",R6="D-R",R6="DN-K",R6="DN-R")),AND(OR(Q6="N-K",Q6="N-R"),OR(R6="DN-K",R6="DN-R"))),1,0) + IF(OR(AND(OR(R6="DN-K",R6="DN-R"),OR(S6="D-K",S6="D-R",S6="DN-K",S6="DN-R")),AND(OR(R6="N-K",R6="N-R"),OR(S6="DN-K",S6="DN-R"))),1,0) + IF(OR(AND(OR(S6="DN-K",S6="DN-R"),OR(T6="D-K",T6="D-R",T6="DN-K",T6="DN-R")),AND(OR(S6="N-K",S6="N-R"),OR(T6="DN-K",T6="DN-R"))),1,0) + IF(OR(AND(OR(T6="DN-K",T6="DN-R"),OR(U6="D-K",U6="D-R",U6="DN-K",U6="DN-R")),AND(OR(T6="N-K",T6="N-R"),OR(U6="DN-K",U6="DN-R"))),1,0) + IF(OR(AND(OR(U6="DN-K",U6="DN-R"),OR(V6="D-K",V6="D-R",V6="DN-K",V6="DN-R")),AND(OR(U6="N-K",U6="N-R"),OR(V6="DN-K",V6="DN-R"))),1,0) + IF(OR(AND(OR(V6="DN-K",V6="DN-R"),OR(W6="D-K",W6="D-R",W6="DN-K",W6="DN-R")),AND(OR(V6="N-K",V6="N-R"),OR(W6="DN-K",W6="DN-R"))),1,0) + IF(OR(AND(OR(W6="DN-K",W6="DN-R"),OR(X6="D-K",X6="D-R",X6="DN-K",X6="DN-R")),AND(OR(W6="N-K",W6="N-R"),OR(X6="DN-K",X6="DN-R"))),1,0) + IF(OR(AND(OR(X6="DN-K",X6="DN-R"),OR(Y6="D-K",Y6="D-R",Y6="DN-K",Y6="DN-R")),AND(OR(X6="N-K",X6="N-R"),OR(Y6="DN-K",Y6="DN-R"))),1,0) + IF(OR(AND(OR(Y6="DN-K",Y6="DN-R"),OR(Z6="D-K",Z6="D-R",Z6="DN-K",Z6="DN-R")),AND(OR(Y6="N-K",Y6="N-R"),OR(Z6="DN-K",Z6="DN-R"))),1,0) + IF(OR(AND(OR(Z6="DN-K",Z6="DN-R"),OR(AA6="D-K",AA6="D-R",AA6="DN-K",AA6="DN-R")),AND(OR(Z6="N-K",Z6="N-R"),OR(AA6="DN-K",AA6="DN-R"))),1,0) + IF(OR(AND(OR(AA6="DN-K",AA6="DN-R"),OR(AB6="D-K",AB6="D-R",AB6="DN-K",AB6="DN-R")),AND(OR(AA6="N-K",AA6="N-R"),OR(AB6="DN-K",AB6="DN-R"))),1,0) + IF(OR(AND(OR(AB6="DN-K",AB6="DN-R"),OR(AC6="D-K",AC6="D-R",AC6="DN-K",AC6="DN-R")),AND(OR(AB6="N-K",AB6="N-R"),OR(AC6="DN-K",AC6="DN-R"))),1,0) + IF(OR(AND(OR(AC6="DN-K",AC6="DN-R"),OR(AD6="D-K",AD6="D-R",AD6="DN-K",AD6="DN-R")),AND(OR(AC6="N-K",AC6="N-R"),OR(AD6="DN-K",AD6="DN-R"))),1,0) + IF(OR(AND(OR(AD6="DN-K",AD6="DN-R"),OR(AE6="D-K",AE6="D-R",AE6="DN-K",AE6="DN-R")),AND(OR(AD6="N-K",AD6="N-R"),OR(AE6="DN-K",AE6="DN-R"))),1,0) + IF(OR(AND(OR(AE6="DN-K",AE6="DN-R"),OR(AF6="D-K",AF6="D-R",AF6="DN-K",AF6="DN-R")),AND(OR(AE6="N-K",AE6="N-R"),OR(AF6="DN-K",AF6="DN-R"))),1,0))>0,"KONFLIKT 36H","OK") -> OK
A7: 3 | B7: Martyna Paweł | C7: =IF(C31="","",C31) | D7: =IF(D31="","",D31) -> DN-K | E7: =IF(E31="","",E31) | F7: =IF(F31="","",F31) | G7: =IF(G31="","",G31) -> DN-K | H7: =IF(H31="","",H31) | I7: =IF(I31="","",I31) | J7: =IF(J31="","",J31) | ... AF7: =IF(AF31="","",AF31) -> DN-K | AH7: =COUNTIF(C7:AF7,"D-K")*12+COUNTIF(C7:AF7,"D-R")*12+COUNTIF(C7:AF7,"N-K")*12+COUNTIF(C7:AF7,"N-R")*12+COUNTIF(C7:AF7,"DN-K")*24+COUNTIF(C7:AF7,"DN-R")*24 -> 120 | AI7: 120 | AJ7: 120 | AK7: =IF(AH7<AI7,"PONIŻEJ MIN",IF(AH7>AJ7,"POWYŻEJ MAX","W NORMIE")) -> W NORMIE | AL7: =IF((IF(OR(AND(OR(C7="DN-K",C7="DN-R"),OR(D7="D-K",D7="D-R",D7="DN-K",D7="DN-R")),AND(OR(C7="N-K",C7="N-R"),OR(D7="DN-K",D7="DN-R"))),1,0) + IF(OR(AND(OR(D7="DN-K",D7="DN-R"),OR(E7="D-K",E7="D-R",E7="DN-K",E7="DN-R")),AND(OR(D7="N-K",D7="N-R"),OR(E7="DN-K",E7="DN-R"))),1,0) + IF(OR(AND(OR(E7="DN-K",E7="DN-R"),OR(F7="D-K",F7="D-R",F7="DN-K",F7="DN-R")),AND(OR(E7="N-K",E7="N-R"),OR(F7="DN-K",F7="DN-R"))),1,0) + IF(OR(AND(OR(F7="DN-K",F7="DN-R"),OR(G7="D-K",G7="D-R",G7="DN-K",G7="DN-R")),AND(OR(F7="N-K",F7="N-R"),OR(G7="DN-K",G7="DN-R"))),1,0) + IF(OR(AND(OR(G7="DN-K",G7="DN-R"),OR(H7="D-K",H7="D-R",H7="DN-K",H7="DN-R")),AND(OR(G7="N-K",G7="N-R"),OR(H7="DN-K",H7="DN-R"))),1,0) + IF(OR(AND(OR(H7="DN-K",H7="DN-R"),OR(I7="D-K",I7="D-R",I7="DN-K",I7="DN-R")),AND(OR(H7="N-K",H7="N-R"),OR(I7="DN-K",I7="DN-R"))),1,0) + IF(OR(AND(OR(I7="DN-K",I7="DN-R"),OR(J7="D-K",J7="D-R",J7="DN-K",J7="DN-R")),AND(OR(I7="N-K",I7="N-R"),OR(J7="DN-K",J7="DN-R"))),1,0) + IF(OR(AND(OR(J7="DN-K",J7="DN-R"),OR(K7="D-K",K7="D-R",K7="DN-K",K7="DN-R")),AND(OR(J7="N-K",J7="N-R"),OR(K7="DN-K",K7="DN-R"))),1,0) + IF(OR(AND(OR(K7="DN-K",K7="DN-R"),OR(L7="D-K",L7="D-R",L7="DN-K",L7="DN-R")),AND(OR(K7="N-K",K7="N-R"),OR(L7="DN-K",L7="DN-R"))),1,0) + IF(OR(AND(OR(L7="DN-K",L7="DN-R"),OR(M7="D-K",M7="D-R",M7="DN-K",M7="DN-R")),AND(OR(L7="N-K",L7="N-R"),OR(M7="DN-K",M7="DN-R"))),1,0) + IF(OR(AND(OR(M7="DN-K",M7="DN-R"),OR(N7="D-K",N7="D-R",N7="DN-K",N7="DN-R")),AND(OR(M7="N-K",M7="N-R"),OR(N7="DN-K",N7="DN-R"))),1,0) + IF(OR(AND(OR(N7="DN-K",N7="DN-R"),OR(O7="D-K",O7="D-R",O7="DN-K",O7="DN-R")),AND(OR(N7="N-K",N7="N-R"),OR(O7="DN-K",O7="DN-R"))),1,0) + IF(OR(AND(OR(O7="DN-K",O7="DN-R"),OR(P7="D-K",P7="D-R",P7="DN-K",P7="DN-R")),AND(OR(O7="N-K",O7="N-R"),OR(P7="DN-K",P7="DN-R"))),1,0) + IF(OR(AND(OR(P7="DN-K",P7="DN-R"),OR(Q7="D-K",Q7="D-R",Q7="DN-K",Q7="DN-R")),AND(OR(P7="N-K",P7="N-R"),OR(Q7="DN-K",Q7="DN-R"))),1,0) + IF(OR(AND(OR(Q7="DN-K",Q7="DN-R"),OR(R7="D-K",R7="D-R",R7="DN-K",R7="DN-R")),AND(OR(Q7="N-K",Q7="N-R"),OR(R7="DN-K",R7="DN-R"))),1,0) + IF(OR(AND(OR(R7="DN-K",R7="DN-R"),OR(S7="D-K",S7="D-R",S7="DN-K",S7="DN-R")),AND(OR(R7="N-K",R7="N-R"),OR(S7="DN-K",S7="DN-R"))),1,0) + IF(OR(AND(OR(S7="DN-K",S7="DN-R"),OR(T7="D-K",T7="D-R",T7="DN-K",T7="DN-R")),AND(OR(S7="N-K",S7="N-R"),OR(T7="DN-K",T7="DN-R"))),1,0) + IF(OR(AND(OR(T7="DN-K",T7="DN-R"),OR(U7="D-K",U7="D-R",U7="DN-K",U7="DN-R")),AND(OR(T7="N-K",T7="N-R"),OR(U7="DN-K",U7="DN-R"))),1,0) + IF(OR(AND(OR(U7="DN-K",U7="DN-R"),OR(V7="D-K",V7="D-R",V7="DN-K",V7="DN-R")),AND(OR(U7="N-K",U7="N-R"),OR(V7="DN-K",V7="DN-R"))),1,0) + IF(OR(AND(OR(V7="DN-K",V7="DN-R"),OR(W7="D-K",W7="D-R",W7="DN-K",W7="DN-R")),AND(OR(V7="N-K",V7="N-R"),OR(W7="DN-K",W7="DN-R"))),1,0) + IF(OR(AND(OR(W7="DN-K",W7="DN-R"),OR(X7="D-K",X7="D-R",X7="DN-K",X7="DN-R")),AND(OR(W7="N-K",W7="N-R"),OR(X7="DN-K",X7="DN-R"))),1,0) + IF(OR(AND(OR(X7="DN-K",X7="DN-R"),OR(Y7="D-K",Y7="D-R",Y7="DN-K",Y7="DN-R")),AND(OR(X7="N-K",X7="N-R"),OR(Y7="DN-K",Y7="DN-R"))),1,0) + IF(OR(AND(OR(Y7="DN-K",Y7="DN-R"),OR(Z7="D-K",Z7="D-R",Z7="DN-K",Z7="DN-R")),AND(OR(Y7="N-K",Y7="N-R"),OR(Z7="DN-K",Z7="DN-R"))),1,0) + IF(OR(AND(OR(Z7="DN-K",Z7="DN-R"),OR(AA7="D-K",AA7="D-R",AA7="DN-K",AA7="DN-R")),AND(OR(Z7="N-K",Z7="N-R"),OR(AA7="DN-K",AA7="DN-R"))),1,0) + IF(OR(AND(OR(AA7="DN-K",AA7="DN-R"),OR(AB7="D-K",AB7="D-R",AB7="DN-K",AB7="DN-R")),AND(OR(AA7="N-K",AA7="N-R"),OR(AB7="DN-K",AB7="DN-R"))),1,0) + IF(OR(AND(OR(AB7="DN-K",AB7="DN-R"),OR(AC7="D-K",AC7="D-R",AC7="DN-K",AC7="DN-R")),AND(OR(AB7="N-K",AB7="N-R"),OR(AC7="DN-K",AC7="DN-R"))),1,0) + IF(OR(AND(OR(AC7="DN-K",AC7="DN-R"),OR(AD7="D-K",AD7="D-R",AD7="DN-K",AD7="DN-R")),AND(OR(AC7="N-K",AC7="N-R"),OR(AD7="DN-K",AD7="DN-R"))),1,0) + IF(OR(AND(OR(AD7="DN-K",AD7="DN-R"),OR(AE7="D-K",AE7="D-R",AE7="DN-K",AE7="DN-R")),AND(OR(AD7="N-K",AD7="N-R"),OR(AE7="DN-K",AE7="DN-R"))),1,0) + IF(OR(AND(OR(AE7="DN-K",AE7="DN-R"),OR(AF7="D-K",AF7="D-R",AF7="DN-K",AF7="DN-R")),AND(OR(AE7="N-K",AE7="N-R"),OR(AF7="DN-K",AF7="DN-R"))),1,0))>0,"KONFLIKT 36H","OK") -> OK
A8: 4 | B8: Michniewicz Tomasz | C8: =IF(C32="","",C32) | D8: =IF(D32="","",D32) | E8: =IF(E32="","",E32) | F8: =IF(F32="","",F32) | G8: =IF(G32="","",G32) | H8: =IF(H32="","",H32) | I8: =IF(I32="","",I32) -> DN-K | J8: =IF(J32="","",J32) | ... AF8: =IF(AF32="","",AF32) | AH8: =COUNTIF(C8:AF8,"D-K")*12+COUNTIF(C8:AF8,"D-R")*12+COUNTIF(C8:AF8,"N-K")*12+COUNTIF(C8:AF8,"N-R")*12+COUNTIF(C8:AF8,"DN-K")*24+COUNTIF(C8:AF8,"DN-R")*24 -> 120 | AI8: 120 | AJ8: 120 | AK8: =IF(AH8<AI8,"PONIŻEJ MIN",IF(AH8>AJ8,"POWYŻEJ MAX","W NORMIE")) -> W NORMIE | AL8: =IF((IF(OR(AND(OR(C8="DN-K",C8="DN-R"),OR(D8="D-K",D8="D-R",D8="DN-K",D8="DN-R")),AND(OR(C8="N-K",C8="N-R"),OR(D8="DN-K",D8="DN-R"))),1,0) + IF(OR(AND(OR(D8="DN-K",D8="DN-R"),OR(E8="D-K",E8="D-R",E8="DN-K",E8="DN-R")),AND(OR(D8="N-K",D8="N-R"),OR(E8="DN-K",E8="DN-R"))),1,0) + IF(OR(AND(OR(E8="DN-K",E8="DN-R"),OR(F8="D-K",F8="D-R",F8="DN-K",F8="DN-R")),AND(OR(E8="N-K",E8="N-R"),OR(F8="DN-K",F8="DN-R"))),1,0) + IF(OR(AND(OR(F8="DN-K",F8="DN-R"),OR(G8="D-K",G8="D-R",G8="DN-K",G8="DN-R")),AND(OR(F8="N-K",F8="N-R"),OR(G8="DN-K",G8="DN-R"))),1,0) + IF(OR(AND(OR(G8="DN-K",G8="DN-R"),OR(H8="D-K",H8="D-R",H8="DN-K",H8="DN-R")),AND(OR(G8="N-K",G8="N-R"),OR(H8="DN-K",H8="DN-R"))),1,0) + IF(OR(AND(OR(H8="DN-K",H8="DN-R"),OR(I8="D-K",I8="D-R",I8="DN-K",I8="DN-R")),AND(OR(H8="N-K",H8="N-R"),OR(I8="DN-K",I8="DN-R"))),1,0) + IF(OR(AND(OR(I8="DN-K",I8="DN-R"),OR(J8="D-K",J8="D-R",J8="DN-K",J8="DN-R")),AND(OR(I8="N-K",I8="N-R"),OR(J8="DN-K",J8="DN-R"))),1,0) + IF(OR(AND(OR(J8="DN-K",J8="DN-R"),OR(K8="D-K",K8="D-R",K8="DN-K",K8="DN-R")),AND(OR(J8="N-K",J8="N-R"),OR(K8="DN-K",K8="DN-R"))),1,0) + IF(OR(AND(OR(K8="DN-K",K8="DN-R"),OR(L8="D-K",L8="D-R",L8="DN-K",L8="DN-R")),AND(OR(K8="N-K",K8="N-R"),OR(L8="DN-K",L8="DN-R"))),1,0) + IF(OR(AND(OR(L8="DN-K",L8="DN-R"),OR(M8="D-K",M8="D-R",M8="DN-K",M8="DN-R")),AND(OR(L8="N-K",L8="N-R"),OR(M8="DN-K",M8="DN-R"))),1,0) + IF(OR(AND(OR(M8="DN-K",M8="DN-R"),OR(N8="D-K",N8="D-R",N8="DN-K",N8="DN-R")),AND(OR(M8="N-K",M8="N-R"),OR(N8="DN-K",N8="DN-R"))),1,0) + IF(OR(AND(OR(N8="DN-K",N8="DN-R"),OR(O8="D-K",O8="D-R",O8="DN-K",O8="DN-R")),AND(OR(N8="N-K",N8="N-R"),OR(O8="DN-K",O8="DN-R"))),1,0) + IF(OR(AND(OR(O8="DN-K",O8="DN-R"),OR(P8="D-K",P8="D-R",P8="DN-K",P8="DN-R")),AND(OR(O8="N-K",O8="N-R"),OR(P8="DN-K",P8="DN-R"))),1,0) + IF(OR(AND(OR(P8="DN-K",P8="DN-R"),OR(Q8="D-K",Q8="D-R",Q8="DN-K",Q8="DN-R")),AND(OR(P8="N-K",P8="N-R"),OR(Q8="DN-K",Q8="DN-R"))),1,0) + IF(OR(AND(OR(Q8="DN-K",Q8="DN-R"),OR(R8="D-K",R8="D-R",R8="DN-K",R8="DN-R")),AND(OR(Q8="N-K",Q8="N-R"),OR(R8="DN-K",R8="DN-R"))),1,0) + IF(OR(AND(OR(R8="DN-K",R8="DN-R"),OR(S8="D-K",S8="D-R",S8="DN-K",S8="DN-R")),AND(OR(R8="N-K",R8="N-R"),OR(S8="DN-K",S8="DN-R"))),1,0) + IF(OR(AND(OR(S8="DN-K",S8="DN-R"),OR(T8="D-K",T8="D-R",T8="DN-K",T8="DN-R")),AND(OR(S8="N-K",S8="N-R"),OR(T8="DN-K",T8="DN-R"))),1,0) + IF(OR(AND(OR(T8="DN-K",T8="DN-R"),OR(U8="D-K",U8="D-R",U8="DN-K",U8="DN-R")),AND(OR(T8="N-K",T8="N-R"),OR(U8="DN-K",U8="DN-R"))),1,0) + IF(OR(AND(OR(U8="DN-K",U8="DN-R"),OR(V8="D-K",V8="D-R",V8="DN-K",V8="DN-R")),AND(OR(U8="N-K",U8="N-R"),OR(V8="DN-K",V8="DN-R"))),1,0) + IF(OR(AND(OR(V8="DN-K",V8="DN-R"),OR(W8="D-K",W8="D-R",W8="DN-K",W8="DN-R")),AND(OR(V8="N-K",V8="N-R"),OR(W8="DN-K",W8="DN-R"))),1,0) + IF(OR(AND(OR(W8="DN-K",W8="DN-R"),OR(X8="D-K",X8="D-R",X8="DN-K",X8="DN-R")),AND(OR(W8="N-K",W8="N-R"),OR(X8="DN-K",X8="DN-R"))),1,0) + IF(OR(AND(OR(X8="DN-K",X8="DN-R"),OR(Y8="D-K",Y8="D-R",Y8="DN-K",Y8="DN-R")),AND(OR(X8="N-K",X8="N-R"),OR(Y8="DN-K",Y8="DN-R"))),1,0) + IF(OR(AND(OR(Y8="DN-K",Y8="DN-R"),OR(Z8="D-K",Z8="D-R",Z8="DN-K",Z8="DN-R")),AND(OR(Y8="N-K",Y8="N-R"),OR(Z8="DN-K",Z8="DN-R"))),1,0) + IF(OR(AND(OR(Z8="DN-K",Z8="DN-R"),OR(AA8="D-K",AA8="D-R",AA8="DN-K",AA8="DN-R")),AND(OR(Z8="N-K",Z8="N-R"),OR(AA8="DN-K",AA8="DN-R"))),1,0) + IF(OR(AND(OR(AA8="DN-K",AA8="DN-R"),OR(AB8="D-K",AB8="D-R",AB8="DN-K",AB8="DN-R")),AND(OR(AA8="N-K",AA8="N-R"),OR(AB8="DN-K",AB8="DN-R"))),1,0) + IF(OR(AND(OR(AB8="DN-K",AB8="DN-R"),OR(AC8="D-K",AC8="D-R",AC8="DN-K",AC8="DN-R")),AND(OR(AB8="N-K",AB8="N-R"),OR(AC8="DN-K",AC8="DN-R"))),1,0) + IF(OR(AND(OR(AC8="DN-K",AC8="DN-R"),OR(AD8="D-K",AD8="D-R",AD8="DN-K",AD8="DN-R")),AND(OR(AC8="N-K",AC8="N-R"),OR(AD8="DN-K",AD8="DN-R"))),1,0) + IF(OR(AND(OR(AD8="DN-K",AD8="DN-R"),OR(AE8="D-K",AE8="D-R",AE8="DN-K",AE8="DN-R")),AND(OR(AD8="N-K",AD8="N-R"),OR(AE8="DN-K",AE8="DN-R"))),1,0) + IF(OR(AND(OR(AE8="DN-K",AE8="DN-R"),OR(AF8="D-K",AF8="D-R",AF8="DN-K",AF8="DN-R")),AND(OR(AE8="N-K",AE8="N-R"),OR(AF8="DN-K",AF8="DN-R"))),1,0))>0,"KONFLIKT 36H","OK") -> OK
A9: 5 | B9: Porzeziński Mateusz | C9: =IF(C33="","",C33) -> DN-K | D9: =IF(D33="","",D33) -> N-R | E9: =IF(E33="","",E33) | F9: =IF(F33="","",F33) -> D-K | G9: =IF(G33="","",G33) | H9: =IF(H33="","",H33) -> DN-K | I9: =IF(I33="","",I33) | J9: =IF(J33="","",J33) | ... AF9: =IF(AF33="","",AF33) | AH9: =COUNTIF(C9:AF9,"D-K")*12+COUNTIF(C9:AF9,"D-R")*12+COUNTIF(C9:AF9,"N-K")*12+COUNTIF(C9:AF9,"N-R")*12+COUNTIF(C9:AF9,"DN-K")*24+COUNTIF(C9:AF9,"DN-R")*24 -> 180 | AI9: 180 | AJ9: 240 | AK9: =IF(AH9<AI9,"PONIŻEJ MIN",IF(AH9>AJ9,"POWYŻEJ MAX","W NORMIE")) -> W NORMIE | AL9: =IF((IF(OR(AND(OR(C9="DN-K",C9="DN-R"),OR(D9="D-K",D9="D-R",D9="DN-K",D9="DN-R")),AND(OR(C9="N-K",C9="N-R"),OR(D9="DN-K",D9="DN-R"))),1,0) + IF(OR(AND(OR(D9="DN-K",D9="DN-R"),OR(E9="D-K",E9="D-R",E9="DN-K",E9="DN-R")),AND(OR(D9="N-K",D9="N-R"),OR(E9="DN-K",E9="DN-R"))),1,0) + IF(OR(AND(OR(E9="DN-K",E9="DN-R"),OR(F9="D-K",F9="D-R",F9="DN-K",F9="DN-R")),AND(OR(E9="N-K",E9="N-R"),OR(F9="DN-K",F9="DN-R"))),1,0) + IF(OR(AND(OR(F9="DN-K",F9="DN-R"),OR(G9="D-K",G9="D-R",G9="DN-K",G9="DN-R")),AND(OR(F9="N-K",F9="N-R"),OR(G9="DN-K",G9="DN-R"))),1,0) + IF(OR(AND(OR(G9="DN-K",G9="DN-R"),OR(H9="D-K",H9="D-R",H9="DN-K",H9="DN-R")),AND(OR(G9="N-K",G9="N-R"),OR(H9="DN-K",H9="DN-R"))),1,0) + IF(OR(AND(OR(H9="DN-K",H9="DN-R"),OR(I9="D-K",I9="D-R",I9="DN-K",I9="DN-R")),AND(OR(H9="N-K",H9="N-R"),OR(I9="DN-K",I9="DN-R"))),1,0) + IF(OR(AND(OR(I9="DN-K",I9="DN-R"),OR(J9="D-K",J9="D-R",J9="DN-K",J9="DN-R")),AND(OR(I9="N-K",I9="N-R"),OR(J9="DN-K",J9="DN-R"))),1,0) + IF(OR(AND(OR(J9="DN-K",J9="DN-R"),OR(K9="D-K",K9="D-R",K9="DN-K",K9="DN-R")),AND(OR(J9="N-K",J9="N-R"),OR(K9="DN-K",K9="DN-R"))),1,0) + IF(OR(AND(OR(K9="DN-K",K9="DN-R"),OR(L9="D-K",L9="D-R",L9="DN-K",L9="DN-R")),AND(OR(K9="N-K",K9="N-R"),OR(L9="DN-K",L9="DN-R"))),1,0) + IF(OR(AND(OR(L9="DN-K",L9="DN-R"),OR(M9="D-K",M9="D-R",M9="DN-K",M9="DN-R")),AND(OR(L9="N-K",L9="N-R"),OR(M9="DN-K",M9="DN-R"))),1,0) + IF(OR(AND(OR(M9="DN-K",M9="DN-R"),OR(N9="D-K",N9="D-R",N9="DN-K",N9="DN-R")),AND(OR(M9="N-K",M9="N-R"),OR(N9="DN-K",N9="DN-R"))),1,0) + IF(OR(AND(OR(N9="DN-K",N9="DN-R"),OR(O9="D-K",O9="D-R",O9="DN-K",O9="DN-R")),AND(OR(N9="N-K",N9="N-R"),OR(O9="DN-K",O9="DN-R"))),1,0) + IF(OR(AND(OR(O9="DN-K",O9="DN-R"),OR(P9="D-K",P9="D-R",P9="DN-K",P9="DN-R")),AND(OR(O9="N-K",O9="N-R"),OR(P9="DN-K",P9="DN-R"))),1,0) + IF(OR(AND(OR(P9="DN-K",P9="DN-R"),OR(Q9="D-K",Q9="D-R",Q9="DN-K",Q9="DN-R")),AND(OR(P9="N-K",P9="N-R"),OR(Q9="DN-K",Q9="DN-R"))),1,0) + IF(OR(AND(OR(Q9="DN-K",Q9="DN-R"),OR(R9="D-K",R9="D-R",R9="DN-K",R9="DN-R")),AND(OR(Q9="N-K",Q9="N-R"),OR(R9="DN-K",R9="DN-R"))),1,0) + IF(OR(AND(OR(R9="DN-K",R9="DN-R"),OR(S9="D-K",S9="D-R",S9="DN-K",S9="DN-R")),AND(OR(R9="N-K",R9="N-R"),OR(S9="DN-K",S9="DN-R"))),1,0) + IF(OR(AND(OR(S9="DN-K",S9="DN-R"),OR(T9="D-K",T9="D-R",T9="DN-K",T9="DN-R")),AND(OR(S9="N-K",S9="N-R"),OR(T9="DN-K",T9="DN-R"))),1,0) + IF(OR(AND(OR(T9="DN-K",T9="DN-R"),OR(U9="D-K",U9="D-R",U9="DN-K",U9="DN-R")),AND(OR(T9="N-K",T9="N-R"),OR(U9="DN-K",U9="DN-R"))),1,0) + IF(OR(AND(OR(U9="DN-K",U9="DN-R"),OR(V9="D-K",V9="D-R",V9="DN-K",V9="DN-R")),AND(OR(U9="N-K",U9="N-R"),OR(V9="DN-K",V9="DN-R"))),1,0) + IF(OR(AND(OR(V9="DN-K",V9="DN-R"),OR(W9="D-K",W9="D-R",W9="DN-K",W9="DN-R")),AND(OR(V9="N-K",V9="N-R"),OR(W9="DN-K",W9="DN-R"))),1,0) + IF(OR(AND(OR(W9="DN-K",W9="DN-R"),OR(X9="D-K",X9="D-R",X9="DN-K",X9="DN-R")),AND(OR(W9="N-K",W9="N-R"),OR(X9="DN-K",X9="DN-R"))),1,0) + IF(OR(AND(OR(X9="DN-K",X9="DN-R"),OR(Y9="D-K",Y9="D-R",Y9="DN-K",Y9="DN-R")),AND(OR(X9="N-K",X9="N-R"),OR(Y9="DN-K",Y9="DN-R"))),1,0) + IF(OR(AND(OR(Y9="DN-K",Y9="DN-R"),OR(Z9="D-K",Z9="D-R",Z9="DN-K",Z9="DN-R")),AND(OR(Y9="N-K",Y9="N-R"),OR(Z9="DN-K",Z9="DN-R"))),1,0) + IF(OR(AND(OR(Z9="DN-K",Z9="DN-R"),OR(AA9="D-K",AA9="D-R",AA9="DN-K",AA9="DN-R")),AND(OR(Z9="N-K",Z9="N-R"),OR(AA9="DN-K",AA9="DN-R"))),1,0) + IF(OR(AND(OR(AA9="DN-K",AA9="DN-R"),OR(AB9="D-K",AB9="D-R",AB9="DN-K",AB9="DN-R")),AND(OR(AA9="N-K",AA9="N-R"),OR(AB9="DN-K",AB9="DN-R"))),1,0) + IF(OR(AND(OR(AB9="DN-K",AB9="DN-R"),OR(AC9="D-K",AC9="D-R",AC9="DN-K",AC9="DN-R")),AND(OR(AB9="N-K",AB9="N-R"),OR(AC9="DN-K",AC9="DN-R"))),1,0) + IF(OR(AND(OR(AC9="DN-K",AC9="DN-R"),OR(AD9="D-K",AD9="D-R",AD9="DN-K",AD9="DN-R")),AND(OR(AC9="N-K",AC9="N-R"),OR(AD9="DN-K",AD9="DN-R"))),1,0) + IF(OR(AND(OR(AD9="DN-K",AD9="DN-R"),OR(AE9="D-K",AE9="D-R",AE9="DN-K",AE9="DN-R")),AND(OR(AD9="N-K",AD9="N-R"),OR(AE9="DN-K",AE9="DN-R"))),1,0) + IF(OR(AND(OR(AE9="DN-K",AE9="DN-R"),OR(AF9="D-K",AF9="D-R",AF9="DN-K",AF9="DN-R")),AND(OR(AE9="N-K",AE9="N-R"),OR(AF9="DN-K",AF9="DN-R"))),1,0))>0,"KONFLIKT 36H","OK") -> OK
A10: 6 | B10: Rogiński Tomasz | C10: =IF(C34="","",C34) -> D-R | D10: =IF(D34="","",D34) | E10: =IF(E34="","",E34) | F10: =IF(F34="","",F34) -> N-K | G10: =IF(G34="","",G34) | H10: =IF(H34="","",H34) | I10: =IF(I34="","",I34) | J10: =IF(J34="","",J34) -> DN-K | ... AF10: =IF(AF34="","",AF34) | AH10: =COUNTIF(C10:AF10,"D-K")*12+COUNTIF(C10:AF10,"D-R")*12+COUNTIF(C10:AF10,"N-K")*12+COUNTIF(C10:AF10,"N-R")*12+COUNTIF(C10:AF10,"DN-K")*24+COUNTIF(C10:AF10,"DN-R")*24 -> 120 | AI10: 120 | AJ10: 120 | AK10: =IF(AH10<AI10,"PONIŻEJ MIN",IF(AH10>AJ10,"POWYŻEJ MAX","W NORMIE")) -> W NORMIE | AL10: =IF((IF(OR(AND(OR(C10="DN-K",C10="DN-R"),OR(D10="D-K",D10="D-R",D10="DN-K",D10="DN-R")),AND(OR(C10="N-K",C10="N-R"),OR(D10="DN-K",D10="DN-R"))),1,0) + IF(OR(AND(OR(D10="DN-K",D10="DN-R"),OR(E10="D-K",E10="D-R",E10="DN-K",E10="DN-R")),AND(OR(D10="N-K",D10="N-R"),OR(E10="DN-K",E10="DN-R"))),1,0) + IF(OR(AND(OR(E10="DN-K",E10="DN-R"),OR(F10="D-K",F10="D-R",F10="DN-K",F10="DN-R")),AND(OR(E10="N-K",E10="N-R"),OR(F10="DN-K",F10="DN-R"))),1,0) + IF(OR(AND(OR(F10="DN-K",F10="DN-R"),OR(G10="D-K",G10="D-R",G10="DN-K",G10="DN-R")),AND(OR(F10="N-K",F10="N-R"),OR(G10="DN-K",G10="DN-R"))),1,0) + IF(OR(AND(OR(G10="DN-K",G10="DN-R"),OR(H10="D-K",H10="D-R",H10="DN-K",H10="DN-R")),AND(OR(G10="N-K",G10="N-R"),OR(H10="DN-K",H10="DN-R"))),1,0) + IF(OR(AND(OR(H10="DN-K",H10="DN-R"),OR(I10="D-K",I10="D-R",I10="DN-K",I10="DN-R")),AND(OR(H10="N-K",H10="N-R"),OR(I10="DN-K",I10="DN-R"))),1,0) + IF(OR(AND(OR(I10="DN-K",I10="DN-R"),OR(J10="D-K",J10="D-R",J10="DN-K",J10="DN-R")),AND(OR(I10="N-K",I10="N-R"),OR(J10="DN-K",J10="DN-R"))),1,0) + IF(OR(AND(OR(J10="DN-K",J10="DN-R"),OR(K10="D-K",K10="D-R",K10="DN-K",K10="DN-R")),AND(OR(J10="N-K",J10="N-R"),OR(K10="DN-K",K10="DN-R"))),1,0) + IF(OR(AND(OR(K10="DN-K",K10="DN-R"),OR(L10="D-K",L10="D-R",L10="DN-K",L10="DN-R")),AND(OR(K10="N-K",K10="N-R"),OR(L10="DN-K",L10="DN-R"))),1,0) + IF(OR(AND(OR(L10="DN-K",L10="DN-R"),OR(M10="D-K",M10="D-R",M10="DN-K",M10="DN-R")),AND(OR(L10="N-K",L10="N-R"),OR(M10="DN-K",M10="DN-R"))),1,0) + IF(OR(AND(OR(M10="DN-K",M10="DN-R"),OR(N10="D-K",N10="D-R",N10="DN-K",N10="DN-R")),AND(OR(M10="N-K",M10="N-R"),OR(N10="DN-K",N10="DN-R"))),1,0) + IF(OR(AND(OR(N10="DN-K",N10="DN-R"),OR(O10="D-K",O10="D-R",O10="DN-K",O10="DN-R")),AND(OR(N10="N-K",N10="N-R"),OR(O10="DN-K",O10="DN-R"))),1,0) + IF(OR(AND(OR(O10="DN-K",O10="DN-R"),OR(P10="D-K",P10="D-R",P10="DN-K",P10="DN-R")),AND(OR(O10="N-K",O10="N-R"),OR(P10="DN-K",P10="DN-R"))),1,0) + IF(OR(AND(OR(P10="DN-K",P10="DN-R"),OR(Q10="D-K",Q10="D-R",Q10="DN-K",Q10="DN-R")),AND(OR(P10="N-K",P10="N-R"),OR(Q10="DN-K",Q10="DN-R"))),1,0) + IF(OR(AND(OR(Q10="DN-K",Q10="DN-R"),OR(R10="D-K",R10="D-R",R10="DN-K",R10="DN-R")),AND(OR(Q10="N-K",Q10="N-R"),OR(R10="DN-K",R10="DN-R"))),1,0) + IF(OR(AND(OR(R10="DN-K",R10="DN-R"),OR(S10="D-K",S10="D-R",S10="DN-K",S10="DN-R")),AND(OR(R10="N-K",R10="N-R"),OR(S10="DN-K",S10="DN-R"))),1,0) + IF(OR(AND(OR(S10="DN-K",S10="DN-R"),OR(T10="D-K",T10="D-R",T10="DN-K",T10="DN-R")),AND(OR(S10="N-K",S10="N-R"),OR(T10="DN-K",T10="DN-R"))),1,0) + IF(OR(AND(OR(T10="DN-K",T10="DN-R"),OR(U10="D-K",U10="D-R",U10="DN-K",U10="DN-R")),AND(OR(T10="N-K",T10="N-R"),OR(U10="DN-K",U10="DN-R"))),1,0) + IF(OR(AND(OR(U10="DN-K",U10="DN-R"),OR(V10="D-K",V10="D-R",V10="DN-K",V10="DN-R")),AND(OR(U10="N-K",U10="N-R"),OR(V10="DN-K",V10="DN-R"))),1,0) + IF(OR(AND(OR(V10="DN-K",V10="DN-R"),OR(W10="D-K",W10="D-R",W10="DN-K",W10="DN-R")),AND(OR(V10="N-K",V10="N-R"),OR(W10="DN-K",W10="DN-R"))),1,0) + IF(OR(AND(OR(W10="DN-K",W10="DN-R"),OR(X10="D-K",X10="D-R",X10="DN-K",X10="DN-R")),AND(OR(W10="N-K",W10="N-R"),OR(X10="DN-K",X10="DN-R"))),1,0) + IF(OR(AND(OR(X10="DN-K",X10="DN-R"),OR(Y10="D-K",Y10="D-R",Y10="DN-K",Y10="DN-R")),AND(OR(X10="N-K",X10="N-R"),OR(Y10="DN-K",Y10="DN-R"))),1,0) + IF(OR(AND(OR(Y10="DN-K",Y10="DN-R"),OR(Z10="D-K",Z10="D-R",Z10="DN-K",Z10="DN-R")),AND(OR(Y10="N-K",Y10="N-R"),OR(Z10="DN-K",Z10="DN-R"))),1,0) + IF(OR(AND(OR(Z10="DN-K",Z10="DN-R"),OR(AA10="D-K",AA10="D-R",AA10="DN-K",AA10="DN-R")),AND(OR(Z10="N-K",Z10="N-R"),OR(AA10="DN-K",AA10="DN-R"))),1,0) + IF(OR(AND(OR(AA10="DN-K",AA10="DN-R"),OR(AB10="D-K",AB10="D-R",AB10="DN-K",AB10="DN-R")),AND(OR(AA10="N-K",AA10="N-R"),OR(AB10="DN-K",AB10="DN-R"))),1,0) + IF(OR(AND(OR(AB10="DN-K",AB10="DN-R"),OR(AC10="D-K",AC10="D-R",AC10="DN-K",AC10="DN-R")),AND(OR(AB10="N-K",AB10="N-R"),OR(AC10="DN-K",AC10="DN-R"))),1,0) + IF(OR(AND(OR(AC10="DN-K",AC10="DN-R"),OR(AD10="D-K",AD10="D-R",AD10="DN-K",AD10="DN-R")),AND(OR(AC10="N-K",AC10="N-R"),OR(AD10="DN-K",AD10="DN-R"))),1,0) + IF(OR(AND(OR(AD10="DN-K",AD10="DN-R"),OR(AE10="D-K",AE10="D-R",AE10="DN-K",AE10="DN-R")),AND(OR(AD10="N-K",AD10="N-R"),OR(AE10="DN-K",AE10="DN-R"))),1,0) + IF(OR(AND(OR(AE10="DN-K",AE10="DN-R"),OR(AF10="D-K",AF10="D-R",AF10="DN-K",AF10="DN-R")),AND(OR(AE10="N-K",AE10="N-R"),OR(AF10="DN-K",AF10="DN-R"))),1,0))>0,"KONFLIKT 36H","OK") -> OK
A11: 7 | B11: Szaryński Tomasz | C11: =IF(C35="","",C35) | D11: =IF(D35="","",D35) | E11: =IF(E35="","",E35) -> DN-R | F11: =IF(F35="","",F35) | G11: =IF(G35="","",G35) | H11: =IF(H35="","",H35) -> DN-R | I11: =IF(I35="","",I35) | J11: =IF(J35="","",J35) | ... AF11: =IF(AF35="","",AF35) | AH11: =COUNTIF(C11:AF11,"D-K")*12+COUNTIF(C11:AF11,"D-R")*12+COUNTIF(C11:AF11,"N-K")*12+COUNTIF(C11:AF11,"N-R")*12+COUNTIF(C11:AF11,"DN-K")*24+COUNTIF(C11:AF11,"DN-R")*24 -> 144 | AI11: 120 | AJ11: 180 | AK11: =IF(AH11<AI11,"PONIŻEJ MIN",IF(AH11>AJ11,"POWYŻEJ MAX","W NORMIE")) -> W NORMIE | AL11: =IF((IF(OR(AND(OR(C11="DN-K",C11="DN-R"),OR(D11="D-K",D11="D-R",D11="DN-K",D11="DN-R")),AND(OR(C11="N-K",C11="N-R"),OR(D11="DN-K",D11="DN-R"))),1,0) + IF(OR(AND(OR(D11="DN-K",D11="DN-R"),OR(E11="D-K",E11="D-R",E11="DN-K",E11="DN-R")),AND(OR(D11="N-K",D11="N-R"),OR(E11="DN-K",E11="DN-R"))),1,0) + IF(OR(AND(OR(E11="DN-K",E11="DN-R"),OR(F11="D-K",F11="D-R",F11="DN-K",F11="DN-R")),AND(OR(E11="N-K",E11="N-R"),OR(F11="DN-K",F11="DN-R"))),1,0) + IF(OR(AND(OR(F11="DN-K",F11="DN-R"),OR(G11="D-K",G11="D-R",G11="DN-K",G11="DN-R")),AND(OR(F11="N-K",F11="N-R"),OR(G11="DN-K",G11="DN-R"))),1,0) + IF(OR(AND(OR(G11="DN-K",G11="DN-R"),OR(H11="D-K",H11="D-R",H11="DN-K",H11="DN-R")),AND(OR(G11="N-K",G11="N-R"),OR(H11="DN-K",H11="DN-R"))),1,0) + IF(OR(AND(OR(H11="DN-K",H11="DN-R"),OR(I11="D-K",I11="D-R",I11="DN-K",I11="DN-R")),AND(OR(H11="N-K",H11="N-R"),OR(I11="DN-K",I11="DN-R"))),1,0) + IF(OR(AND(OR(I11="DN-K",I11="DN-R"),OR(J11="D-K",J11="D-R",J11="DN-K",J11="DN-R")),AND(OR(I11="N-K",I11="N-R"),OR(J11="DN-K",J11="DN-R"))),1,0) + IF(OR(AND(OR(J11="DN-K",J11="DN-R"),OR(K11="D-K",K11="D-R",K11="DN-K",K11="DN-R")),AND(OR(J11="N-K",J11="N-R"),OR(K11="DN-K",K11="DN-R"))),1,0) + IF(OR(AND(OR(K11="DN-K",K11="DN-R"),OR(L11="D-K",L11="D-R",L11="DN-K",L11="DN-R")),AND(OR(K11="N-K",K11="N-R"),OR(L11="DN-K",L11="DN-R"))),1,0) + IF(OR(AND(OR(L11="DN-K",L11="DN-R"),OR(M11="D-K",M11="D-R",M11="DN-K",M11="DN-R")),AND(OR(L11="N-K",L11="N-R"),OR(M11="DN-K",M11="DN-R"))),1,0) + IF(OR(AND(OR(M11="DN-K",M11="DN-R"),OR(N11="D-K",N11="D-R",N11="DN-K",N11="DN-R")),AND(OR(M11="N-K",M11="N-R"),OR(N11="DN-K",N11="DN-R"))),1,0) + IF(OR(AND(OR(N11="DN-K",N11="DN-R"),OR(O11="D-K",O11="D-R",O11="DN-K",O11="DN-R")),AND(OR(N11="N-K",N11="N-R"),OR(O11="DN-K",O11="DN-R"))),1,0) + IF(OR(AND(OR(O11="DN-K",O11="DN-R"),OR(P11="D-K",P11="D-R",P11="DN-K",P11="DN-R")),AND(OR(O11="N-K",O11="N-R"),OR(P11="DN-K",P11="DN-R"))),1,0) + IF(OR(AND(OR(P11="DN-K",P11="DN-R"),OR(Q11="D-K",Q11="D-R",Q11="DN-K",Q11="DN-R")),AND(OR(P11="N-K",P11="N-R"),OR(Q11="DN-K",Q11="DN-R"))),1,0) + IF(OR(AND(OR(Q11="DN-K",Q11="DN-R"),OR(R11="D-K",R11="D-R",R11="DN-K",R11="DN-R")),AND(OR(Q11="N-K",Q11="N-R"),OR(R11="DN-K",R11="DN-R"))),1,0) + IF(OR(AND(OR(R11="DN-K",R11="DN-R"),OR(S11="D-K",S11="D-R",S11="DN-K",S11="DN-R")),AND(OR(R11="N-K",R11="N-R"),OR(S11="DN-K",S11="DN-R"))),1,0) + IF(OR(AND(OR(S11="DN-K",S11="DN-R"),OR(T11="D-K",T11="D-R",T11="DN-K",T11="DN-R")),AND(OR(S11="N-K",S11="N-R"),OR(T11="DN-K",T11="DN-R"))),1,0) + IF(OR(AND(OR(T11="DN-K",T11="DN-R"),OR(U11="D-K",U11="D-R",U11="DN-K",U11="DN-R")),AND(OR(T11="N-K",T11="N-R"),OR(U11="DN-K",U11="DN-R"))),1,0) + IF(OR(AND(OR(U11="DN-K",U11="DN-R"),OR(V11="D-K",V11="D-R",V11="DN-K",V11="DN-R")),AND(OR(U11="N-K",U11="N-R"),OR(V11="DN-K",V11="DN-R"))),1,0) + IF(OR(AND(OR(V11="DN-K",V11="DN-R"),OR(W11="D-K",W11="D-R",W11="DN-K",W11="DN-R")),AND(OR(V11="N-K",V11="N-R"),OR(W11="DN-K",W11="DN-R"))),1,0) + IF(OR(AND(OR(W11="DN-K",W11="DN-R"),OR(X11="D-K",X11="D-R",X11="DN-K",X11="DN-R")),AND(OR(W11="N-K",W11="N-R"),OR(X11="DN-K",X11="DN-R"))),1,0) + IF(OR(AND(OR(X11="DN-K",X11="DN-R"),OR(Y11="D-K",Y11="D-R",Y11="DN-K",Y11="DN-R")),AND(OR(X11="N-K",X11="N-R"),OR(Y11="DN-K",Y11="DN-R"))),1,0) + IF(OR(AND(OR(Y11="DN-K",Y11="DN-R"),OR(Z11="D-K",Z11="D-R",Z11="DN-K",Z11="DN-R")),AND(OR(Y11="N-K",Y11="N-R"),OR(Z11="DN-K",Z11="DN-R"))),1,0) + IF(OR(AND(OR(Z11="DN-K",Z11="DN-R"),OR(AA11="D-K",AA11="D-R",AA11="DN-K",AA11="DN-R")),AND(OR(Z11="N-K",Z11="N-R"),OR(AA11="DN-K",AA11="DN-R"))),1,0) + IF(OR(AND(OR(AA11="DN-K",AA11="DN-R"),OR(AB11="D-K",AB11="D-R",AB11="DN-K",AB11="DN-R")),AND(OR(AA11="N-K",AA11="N-R"),OR(AB11="DN-K",AB11="DN-R"))),1,0) + IF(OR(AND(OR(AB11="DN-K",AB11="DN-R"),OR(AC11="D-K",AC11="D-R",AC11="DN-K",AC11="DN-R")),AND(OR(AB11="N-K",AB11="N-R"),OR(AC11="DN-K",AC11="DN-R"))),1,0) + IF(OR(AND(OR(AC11="DN-K",AC11="DN-R"),OR(AD11="D-K",AD11="D-R",AD11="DN-K",AD11="DN-R")),AND(OR(AC11="N-K",AC11="N-R"),OR(AD11="DN-K",AD11="DN-R"))),1,0) + IF(OR(AND(OR(AD11="DN-K",AD11="DN-R"),OR(AE11="D-K",AE11="D-R",AE11="DN-K",AE11="DN-R")),AND(OR(AD11="N-K",AD11="N-R"),OR(AE11="DN-K",AE11="DN-R"))),1,0) + IF(OR(AND(OR(AE11="DN-K",AE11="DN-R"),OR(AF11="D-K",AF11="D-R",AF11="DN-K",AF11="DN-R")),AND(OR(AE11="N-K",AE11="N-R"),OR(AF11="DN-K",AF11="DN-R"))),1,0))>0,"KONFLIKT 36H","OK") -> OK
A12: 8 | B12: Szymański Tomasz | C12: =IF(C36="","",C36) -> N-R | D12: =IF(D36="","",D36) -> D-R | E12: =IF(E36="","",E36) | F12: =IF(F36="","",F36) | G12: =IF(G36="","",G36) -> D-R | H12: =IF(H36="","",H36) | I12: =IF(I36="","",I36) -> DN-R | J12: =IF(J36="","",J36) | ... AF12: =IF(AF36="","",AF36) | AH12: =COUNTIF(C12:AF12,"D-K")*12+COUNTIF(C12:AF12,"D-R")*12+COUNTIF(C12:AF12,"N-K")*12+COUNTIF(C12:AF12,"N-R")*12+COUNTIF(C12:AF12,"DN-K")*24+COUNTIF(C12:AF12,"DN-R")*24 -> 168 | AI12: 120 | AJ12: 180 | AK12: =IF(AH12<AI12,"PONIŻEJ MIN",IF(AH12>AJ12,"POWYŻEJ MAX","W NORMIE")) -> W NORMIE | AL12: =IF((IF(OR(AND(OR(C12="DN-K",C12="DN-R"),OR(D12="D-K",D12="D-R",D12="DN-K",D12="DN-R")),AND(OR(C12="N-K",C12="N-R"),OR(D12="DN-K",D12="DN-R"))),1,0) + IF(OR(AND(OR(D12="DN-K",D12="DN-R"),OR(E12="D-K",E12="D-R",E12="DN-K",E12="DN-R")),AND(OR(D12="N-K",D12="N-R"),OR(E12="DN-K",E12="DN-R"))),1,0) + IF(OR(AND(OR(E12="DN-K",E12="DN-R"),OR(F12="D-K",F12="D-R",F12="DN-K",F12="DN-R")),AND(OR(E12="N-K",E12="N-R"),OR(F12="DN-K",F12="DN-R"))),1,0) + IF(OR(AND(OR(F12="DN-K",F12="DN-R"),OR(G12="D-K",G12="D-R",G12="DN-K",G12="DN-R")),AND(OR(F12="N-K",F12="N-R"),OR(G12="DN-K",G12="DN-R"))),1,0) + IF(OR(AND(OR(G12="DN-K",G12="DN-R"),OR(H12="D-K",H12="D-R",H12="DN-K",H12="DN-R")),AND(OR(G12="N-K",G12="N-R"),OR(H12="DN-K",H12="DN-R"))),1,0) + IF(OR(AND(OR(H12="DN-K",H12="DN-R"),OR(I12="D-K",I12="D-R",I12="DN-K",I12="DN-R")),AND(OR(H12="N-K",H12="N-R"),OR(I12="DN-K",I12="DN-R"))),1,0) + IF(OR(AND(OR(I12="DN-K",I12="DN-R"),OR(J12="D-K",J12="D-R",J12="DN-K",J12="DN-R")),AND(OR(I12="N-K",I12="N-R"),OR(J12="DN-K",J12="DN-R"))),1,0) + IF(OR(AND(OR(J12="DN-K",J12="DN-R"),OR(K12="D-K",K12="D-R",K12="DN-K",K12="DN-R")),AND(OR(J12="N-K",J12="N-R"),OR(K12="DN-K",K12="DN-R"))),1,0) + IF(OR(AND(OR(K12="DN-K",K12="DN-R"),OR(L12="D-K",L12="D-R",L12="DN-K",L12="DN-R")),AND(OR(K12="N-K",K12="N-R"),OR(L12="DN-K",L12="DN-R"))),1,0) + IF(OR(AND(OR(L12="DN-K",L12="DN-R"),OR(M12="D-K",M12="D-R",M12="DN-K",M12="DN-R")),AND(OR(L12="N-K",L12="N-R"),OR(M12="DN-K",M12="DN-R"))),1,0) + IF(OR(AND(OR(M12="DN-K",M12="DN-R"),OR(N12="D-K",N12="D-R",N12="DN-K",N12="DN-R")),AND(OR(M12="N-K",M12="N-R"),OR(N12="DN-K",N12="DN-R"))),1,0) + IF(OR(AND(OR(N12="DN-K",N12="DN-R"),OR(O12="D-K",O12="D-R",O12="DN-K",O12="DN-R")),AND(OR(N12="N-K",N12="N-R"),OR(O12="DN-K",O12="DN-R"))),1,0) + IF(OR(AND(OR(O12="DN-K",O12="DN-R"),OR(P12="D-K",P12="D-R",P12="DN-K",P12="DN-R")),AND(OR(O12="N-K",O12="N-R"),OR(P12="DN-K",P12="DN-R"))),1,0) + IF(OR(AND(OR(P12="DN-K",P12="DN-R"),OR(Q12="D-K",Q12="D-R",Q12="DN-K",Q12="DN-R")),AND(OR(P12="N-K",P12="N-R"),OR(Q12="DN-K",Q12="DN-R"))),1,0) + IF(OR(AND(OR(Q12="DN-K",Q12="DN-R"),OR(R12="D-K",R12="D-R",R12="DN-K",R12="DN-R")),AND(OR(Q12="N-K",Q12="N-R"),OR(R12="DN-K",R12="DN-R"))),1,0) + IF(OR(AND(OR(R12="DN-K",R12="DN-R"),OR(S12="D-K",S12="D-R",S12="DN-K",S12="DN-R")),AND(OR(R12="N-K",R12="N-R"),OR(S12="DN-K",S12="DN-R"))),1,0) + IF(OR(AND(OR(S12="DN-K",S12="DN-R"),OR(T12="D-K",T12="D-R",T12="DN-K",T12="DN-R")),AND(OR(S12="N-K",S12="N-R"),OR(T12="DN-K",T12="DN-R"))),1,0) + IF(OR(AND(OR(T12="DN-K",T12="DN-R"),OR(U12="D-K",U12="D-R",U12="DN-K",U12="DN-R")),AND(OR(T12="N-K",T12="N-R"),OR(U12="DN-K",U12="DN-R"))),1,0) + IF(OR(AND(OR(U12="DN-K",U12="DN-R"),OR(V12="D-K",V12="D-R",V12="DN-K",V12="DN-R")),AND(OR(U12="N-K",U12="N-R"),OR(V12="DN-K",V12="DN-R"))),1,0) + IF(OR(AND(OR(V12="DN-K",V12="DN-R"),OR(W12="D-K",W12="D-R",W12="DN-K",W12="DN-R")),AND(OR(V12="N-K",V12="N-R"),OR(W12="DN-K",W12="DN-R"))),1,0) + IF(OR(AND(OR(W12="DN-K",W12="DN-R"),OR(X12="D-K",X12="D-R",X12="DN-K",X12="DN-R")),AND(OR(W12="N-K",W12="N-R"),OR(X12="DN-K",X12="DN-R"))),1,0) + IF(OR(AND(OR(X12="DN-K",X12="DN-R"),OR(Y12="D-K",Y12="D-R",Y12="DN-K",Y12="DN-R")),AND(OR(X12="N-K",X12="N-R"),OR(Y12="DN-K",Y12="DN-R"))),1,0) + IF(OR(AND(OR(Y12="DN-K",Y12="DN-R"),OR(Z12="D-K",Z12="D-R",Z12="DN-K",Z12="DN-R")),AND(OR(Y12="N-K",Y12="N-R"),OR(Z12="DN-K",Z12="DN-R"))),1,0) + IF(OR(AND(OR(Z12="DN-K",Z12="DN-R"),OR(AA12="D-K",AA12="D-R",AA12="DN-K",AA12="DN-R")),AND(OR(Z12="N-K",Z12="N-R"),OR(AA12="DN-K",AA12="DN-R"))),1,0) + IF(OR(AND(OR(AA12="DN-K",AA12="DN-R"),OR(AB12="D-K",AB12="D-R",AB12="DN-K",AB12="DN-R")),AND(OR(AA12="N-K",AA12="N-R"),OR(AB12="DN-K",AB12="DN-R"))),1,0) + IF(OR(AND(OR(AB12="DN-K",AB12="DN-R"),OR(AC12="D-K",AC12="D-R",AC12="DN-K",AC12="DN-R")),AND(OR(AB12="N-K",AB12="N-R"),OR(AC12="DN-K",AC12="DN-R"))),1,0) + IF(OR(AND(OR(AC12="DN-K",AC12="DN-R"),OR(AD12="D-K",AD12="D-R",AD12="DN-K",AD12="DN-R")),AND(OR(AC12="N-K",AC12="N-R"),OR(AD12="DN-K",AD12="DN-R"))),1,0) + IF(OR(AND(OR(AD12="DN-K",AD12="DN-R"),OR(AE12="D-K",AE12="D-R",AE12="DN-K",AE12="DN-R")),AND(OR(AD12="N-K",AD12="N-R"),OR(AE12="DN-K",AE12="DN-R"))),1,0) + IF(OR(AND(OR(AE12="DN-K",AE12="DN-R"),OR(AF12="D-K",AF12="D-R",AF12="DN-K",AF12="DN-R")),AND(OR(AE12="N-K",AE12="N-R"),OR(AF12="DN-K",AF12="DN-R"))),1,0))>0,"KONFLIKT 36H","OK") -> OK
A13: 9 | B13: Tekien Marek | C13: =IF(C37="","",C37) | D13: =IF(D37="","",D37) | E13: =IF(E37="","",E37) | F13: =IF(F37="","",F37) | G13: =IF(G37="","",G37) | H13: =IF(H37="","",H37) | I13: =IF(I37="","",I37) | J13: =IF(J37="","",J37) | ... AF13: =IF(AF37="","",AF37) -> DN-R | AH13: =COUNTIF(C13:AF13,"D-K")*12+COUNTIF(C13:AF13,"D-R")*12+COUNTIF(C13:AF13,"N-K")*12+COUNTIF(C13:AF13,"N-R")*12+COUNTIF(C13:AF13,"DN-K")*24+COUNTIF(C13:AF13,"DN-R")*24 -> 120 | AI13: 120 | AJ13: 120 | AK13: =IF(AH13<AI13,"PONIŻEJ MIN",IF(AH13>AJ13,"POWYŻEJ MAX","W NORMIE")) -> W NORMIE | AL13: =IF((IF(OR(AND(OR(C13="DN-K",C13="DN-R"),OR(D13="D-K",D13="D-R",D13="DN-K",D13="DN-R")),AND(OR(C13="N-K",C13="N-R"),OR(D13="DN-K",D13="DN-R"))),1,0) + IF(OR(AND(OR(D13="DN-K",D13="DN-R"),OR(E13="D-K",E13="D-R",E13="DN-K",E13="DN-R")),AND(OR(D13="N-K",D13="N-R"),OR(E13="DN-K",E13="DN-R"))),1,0) + IF(OR(AND(OR(E13="DN-K",E13="DN-R"),OR(F13="D-K",F13="D-R",F13="DN-K",F13="DN-R")),AND(OR(E13="N-K",E13="N-R"),OR(F13="DN-K",F13="DN-R"))),1,0) + IF(OR(AND(OR(F13="DN-K",F13="DN-R"),OR(G13="D-K",G13="D-R",G13="DN-K",G13="DN-R")),AND(OR(F13="N-K",F13="N-R"),OR(G13="DN-K",G13="DN-R"))),1,0) + IF(OR(AND(OR(G13="DN-K",G13="DN-R"),OR(H13="D-K",H13="D-R",H13="DN-K",H13="DN-R")),AND(OR(G13="N-K",G13="N-R"),OR(H13="DN-K",H13="DN-R"))),1,0) + IF(OR(AND(OR(H13="DN-K",H13="DN-R"),OR(I13="D-K",I13="D-R",I13="DN-K",I13="DN-R")),AND(OR(H13="N-K",H13="N-R"),OR(I13="DN-K",I13="DN-R"))),1,0) + IF(OR(AND(OR(I13="DN-K",I13="DN-R"),OR(J13="D-K",J13="D-R",J13="DN-K",J13="DN-R")),AND(OR(I13="N-K",I13="N-R"),OR(J13="DN-K",J13="DN-R"))),1,0) + IF(OR(AND(OR(J13="DN-K",J13="DN-R"),OR(K13="D-K",K13="D-R",K13="DN-K",K13="DN-R")),AND(OR(J13="N-K",J13="N-R"),OR(K13="DN-K",K13="DN-R"))),1,0) + IF(OR(AND(OR(K13="DN-K",K13="DN-R"),OR(L13="D-K",L13="D-R",L13="DN-K",L13="DN-R")),AND(OR(K13="N-K",K13="N-R"),OR(L13="DN-K",L13="DN-R"))),1,0) + IF(OR(AND(OR(L13="DN-K",L13="DN-R"),OR(M13="D-K",M13="D-R",M13="DN-K",M13="DN-R")),AND(OR(L13="N-K",L13="N-R"),OR(M13="DN-K",M13="DN-R"))),1,0) + IF(OR(AND(OR(M13="DN-K",M13="DN-R"),OR(N13="D-K",N13="D-R",N13="DN-K",N13="DN-R")),AND(OR(M13="N-K",M13="N-R"),OR(N13="DN-K",N13="DN-R"))),1,0) + IF(OR(AND(OR(N13="DN-K",N13="DN-R"),OR(O13="D-K",O13="D-R",O13="DN-K",O13="DN-R")),AND(OR(N13="N-K",N13="N-R"),OR(O13="DN-K",O13="DN-R"))),1,0) + IF(OR(AND(OR(O13="DN-K",O13="DN-R"),OR(P13="D-K",P13="D-R",P13="DN-K",P13="DN-R")),AND(OR(O13="N-K",O13="N-R"),OR(P13="DN-K",P13="DN-R"))),1,0) + IF(OR(AND(OR(P13="DN-K",P13="DN-R"),OR(Q13="D-K",Q13="D-R",Q13="DN-K",Q13="DN-R")),AND(OR(P13="N-K",P13="N-R"),OR(Q13="DN-K",Q13="DN-R"))),1,0) + IF(OR(AND(OR(Q13="DN-K",Q13="DN-R"),OR(R13="D-K",R13="D-R",R13="DN-K",R13="DN-R")),AND(OR(Q13="N-K",Q13="N-R"),OR(R13="DN-K",R13="DN-R"))),1,0) + IF(OR(AND(OR(R13="DN-K",R13="DN-R"),OR(S13="D-K",S13="D-R",S13="DN-K",S13="DN-R")),AND(OR(R13="N-K",R13="N-R"),OR(S13="DN-K",S13="DN-R"))),1,0) + IF(OR(AND(OR(S13="DN-K",S13="DN-R"),OR(T13="D-K",T13="D-R",T13="DN-K",T13="DN-R")),AND(OR(S13="N-K",S13="N-R"),OR(T13="DN-K",T13="DN-R"))),1,0) + IF(OR(AND(OR(T13="DN-K",T13="DN-R"),OR(U13="D-K",U13="D-R",U13="DN-K",U13="DN-R")),AND(OR(T13="N-K",T13="N-R"),OR(U13="DN-K",U13="DN-R"))),1,0) + IF(OR(AND(OR(U13="DN-K",U13="DN-R"),OR(V13="D-K",V13="D-R",V13="DN-K",V13="DN-R")),AND(OR(U13="N-K",U13="N-R"),OR(V13="DN-K",V13="DN-R"))),1,0) + IF(OR(AND(OR(V13="DN-K",V13="DN-R"),OR(W13="D-K",W13="D-R",W13="DN-K",W13="DN-R")),AND(OR(V13="N-K",V13="N-R"),OR(W13="DN-K",W13="DN-R"))),1,0) + IF(OR(AND(OR(W13="DN-K",W13="DN-R"),OR(X13="D-K",X13="D-R",X13="DN-K",X13="DN-R")),AND(OR(W13="N-K",W13="N-R"),OR(X13="DN-K",X13="DN-R"))),1,0) + IF(OR(AND(OR(X13="DN-K",X13="DN-R"),OR(Y13="D-K",Y13="D-R",Y13="DN-K",Y13="DN-R")),AND(OR(X13="N-K",X13="N-R"),OR(Y13="DN-K",Y13="DN-R"))),1,0) + IF(OR(AND(OR(Y13="DN-K",Y13="DN-R"),OR(Z13="D-K",Z13="D-R",Z13="DN-K",Z13="DN-R")),AND(OR(Y13="N-K",Y13="N-R"),OR(Z13="DN-K",Z13="DN-R"))),1,0) + IF(OR(AND(OR(Z13="DN-K",Z13="DN-R"),OR(AA13="D-K",AA13="D-R",AA13="DN-K",AA13="DN-R")),AND(OR(Z13="N-K",Z13="N-R"),OR(AA13="DN-K",AA13="DN-R"))),1,0) + IF(OR(AND(OR(AA13="DN-K",AA13="DN-R"),OR(AB13="D-K",AB13="D-R",AB13="DN-K",AB13="DN-R")),AND(OR(AA13="N-K",AA13="N-R"),OR(AB13="DN-K",AB13="DN-R"))),1,0) + IF(OR(AND(OR(AB13="DN-K",AB13="DN-R"),OR(AC13="D-K",AC13="D-R",AC13="DN-K",AC13="DN-R")),AND(OR(AB13="N-K",AB13="N-R"),OR(AC13="DN-K",AC13="DN-R"))),1,0) + IF(OR(AND(OR(AC13="DN-K",AC13="DN-R"),OR(AD13="D-K",AD13="D-R",AD13="DN-K",AD13="DN-R")),AND(OR(AC13="N-K",AC13="N-R"),OR(AD13="DN-K",AD13="DN-R"))),1,0) + IF(OR(AND(OR(AD13="DN-K",AD13="DN-R"),OR(AE13="D-K",AE13="D-R",AE13="DN-K",AE13="DN-R")),AND(OR(AD13="N-K",AD13="N-R"),OR(AE13="DN-K",AE13="DN-R"))),1,0) + IF(OR(AND(OR(AE13="DN-K",AE13="DN-R"),OR(AF13="D-K",AF13="D-R",AF13="DN-K",AF13="DN-R")),AND(OR(AE13="N-K",AE13="N-R"),OR(AF13="DN-K",AF13="DN-R"))),1,0))>0,"KONFLIKT 36H","OK") -> OK
A14: 10 | B14: Turzyński Krystian | C14: =IF(C38="","",C38) | D14: =IF(D38="","",D38) | E14: =IF(E38="","",E38) | F14: =IF(F38="","",F38) | G14: =IF(G38="","",G38) | H14: =IF(H38="","",H38) | I14: =IF(I38="","",I38) | J14: =IF(J38="","",J38) -> DN-R | ... AF14: =IF(AF38="","",AF38) | AH14: =COUNTIF(C14:AF14,"D-K")*12+COUNTIF(C14:AF14,"D-R")*12+COUNTIF(C14:AF14,"N-K")*12+COUNTIF(C14:AF14,"N-R")*12+COUNTIF(C14:AF14,"DN-K")*24+COUNTIF(C14:AF14,"DN-R")*24 -> 156 | AI14: 120 | AJ14: 180 | AK14: =IF(AH14<AI14,"PONIŻEJ MIN",IF(AH14>AJ14,"POWYŻEJ MAX","W NORMIE")) -> W NORMIE | AL14: =IF((IF(OR(AND(OR(C14="DN-K",C14="DN-R"),OR(D14="D-K",D14="D-R",D14="DN-K",D14="DN-R")),AND(OR(C14="N-K",C14="N-R"),OR(D14="DN-K",D14="DN-R"))),1,0) + IF(OR(AND(OR(D14="DN-K",D14="DN-R"),OR(E14="D-K",E14="D-R",E14="DN-K",E14="DN-R")),AND(OR(D14="N-K",D14="N-R"),OR(E14="DN-K",E14="DN-R"))),1,0) + IF(OR(AND(OR(E14="DN-K",E14="DN-R"),OR(F14="D-K",F14="D-R",F14="DN-K",F14="DN-R")),AND(OR(E14="N-K",E14="N-R"),OR(F14="DN-K",F14="DN-R"))),1,0) + IF(OR(AND(OR(F14="DN-K",F14="DN-R"),OR(G14="D-K",G14="D-R",G14="DN-K",G14="DN-R")),AND(OR(F14="N-K",F14="N-R"),OR(G14="DN-K",G14="DN-R"))),1,0) + IF(OR(AND(OR(G14="DN-K",G14="DN-R"),OR(H14="D-K",H14="D-R",H14="DN-K",H14="DN-R")),AND(OR(G14="N-K",G14="N-R"),OR(H14="DN-K",H14="DN-R"))),1,0) + IF(OR(AND(OR(H14="DN-K",H14="DN-R"),OR(I14="D-K",I14="D-R",I14="DN-K",I14="DN-R")),AND(OR(H14="N-K",H14="N-R"),OR(I14="DN-K",I14="DN-R"))),1,0) + IF(OR(AND(OR(I14="DN-K",I14="DN-R"),OR(J14="D-K",J14="D-R",J14="DN-K",J14="DN-R")),AND(OR(I14="N-K",I14="N-R"),OR(J14="DN-K",J14="DN-R"))),1,0) + IF(OR(AND(OR(J14="DN-K",J14="DN-R"),OR(K14="D-K",K14="D-R",K14="DN-K",K14="DN-R")),AND(OR(J14="N-K",J14="N-R"),OR(K14="DN-K",K14="DN-R"))),1,0) + IF(OR(AND(OR(K14="DN-K",K14="DN-R"),OR(L14="D-K",L14="D-R",L14="DN-K",L14="DN-R")),AND(OR(K14="N-K",K14="N-R"),OR(L14="DN-K",L14="DN-R"))),1,0) + IF(OR(AND(OR(L14="DN-K",L14="DN-R"),OR(M14="D-K",M14="D-R",M14="DN-K",M14="DN-R")),AND(OR(L14="N-K",L14="N-R"),OR(M14="DN-K",M14="DN-R"))),1,0) + IF(OR(AND(OR(M14="DN-K",M14="DN-R"),OR(N14="D-K",N14="D-R",N14="DN-K",N14="DN-R")),AND(OR(M14="N-K",M14="N-R"),OR(N14="DN-K",N14="DN-R"))),1,0) + IF(OR(AND(OR(N14="DN-K",N14="DN-R"),OR(O14="D-K",O14="D-R",O14="DN-K",O14="DN-R")),AND(OR(N14="N-K",N14="N-R"),OR(O14="DN-K",O14="DN-R"))),1,0) + IF(OR(AND(OR(O14="DN-K",O14="DN-R"),OR(P14="D-K",P14="D-R",P14="DN-K",P14="DN-R")),AND(OR(O14="N-K",O14="N-R"),OR(P14="DN-K",P14="DN-R"))),1,0) + IF(OR(AND(OR(P14="DN-K",P14="DN-R"),OR(Q14="D-K",Q14="D-R",Q14="DN-K",Q14="DN-R")),AND(OR(P14="N-K",P14="N-R"),OR(Q14="DN-K",Q14="DN-R"))),1,0) + IF(OR(AND(OR(Q14="DN-K",Q14="DN-R"),OR(R14="D-K",R14="D-R",R14="DN-K",R14="DN-R")),AND(OR(Q14="N-K",Q14="N-R"),OR(R14="DN-K",R14="DN-R"))),1,0) + IF(OR(AND(OR(R14="DN-K",R14="DN-R"),OR(S14="D-K",S14="D-R",S14="DN-K",S14="DN-R")),AND(OR(R14="N-K",R14="N-R"),OR(S14="DN-K",S14="DN-R"))),1,0) + IF(OR(AND(OR(S14="DN-K",S14="DN-R"),OR(T14="D-K",T14="D-R",T14="DN-K",T14="DN-R")),AND(OR(S14="N-K",S14="N-R"),OR(T14="DN-K",T14="DN-R"))),1,0) + IF(OR(AND(OR(T14="DN-K",T14="DN-R"),OR(U14="D-K",U14="D-R",U14="DN-K",U14="DN-R")),AND(OR(T14="N-K",T14="N-R"),OR(U14="DN-K",U14="DN-R"))),1,0) + IF(OR(AND(OR(U14="DN-K",U14="DN-R"),OR(V14="D-K",V14="D-R",V14="DN-K",V14="DN-R")),AND(OR(U14="N-K",U14="N-R"),OR(V14="DN-K",V14="DN-R"))),1,0) + IF(OR(AND(OR(V14="DN-K",V14="DN-R"),OR(W14="D-K",W14="D-R",W14="DN-K",W14="DN-R")),AND(OR(V14="N-K",V14="N-R"),OR(W14="DN-K",W14="DN-R"))),1,0) + IF(OR(AND(OR(W14="DN-K",W14="DN-R"),OR(X14="D-K",X14="D-R",X14="DN-K",X14="DN-R")),AND(OR(W14="N-K",W14="N-R"),OR(X14="DN-K",X14="DN-R"))),1,0) + IF(OR(AND(OR(X14="DN-K",X14="DN-R"),OR(Y14="D-K",Y14="D-R",Y14="DN-K",Y14="DN-R")),AND(OR(X14="N-K",X14="N-R"),OR(Y14="DN-K",Y14="DN-R"))),1,0) + IF(OR(AND(OR(Y14="DN-K",Y14="DN-R"),OR(Z14="D-K",Z14="D-R",Z14="DN-K",Z14="DN-R")),AND(OR(Y14="N-K",Y14="N-R"),OR(Z14="DN-K",Z14="DN-R"))),1,0) + IF(OR(AND(OR(Z14="DN-K",Z14="DN-R"),OR(AA14="D-K",AA14="D-R",AA14="DN-K",AA14="DN-R")),AND(OR(Z14="N-K",Z14="N-R"),OR(AA14="DN-K",AA14="DN-R"))),1,0) + IF(OR(AND(OR(AA14="DN-K",AA14="DN-R"),OR(AB14="D-K",AB14="D-R",AB14="DN-K",AB14="DN-R")),AND(OR(AA14="N-K",AA14="N-R"),OR(AB14="DN-K",AB14="DN-R"))),1,0) + IF(OR(AND(OR(AB14="DN-K",AB14="DN-R"),OR(AC14="D-K",AC14="D-R",AC14="DN-K",AC14="DN-R")),AND(OR(AB14="N-K",AB14="N-R"),OR(AC14="DN-K",AC14="DN-R"))),1,0) + IF(OR(AND(OR(AC14="DN-K",AC14="DN-R"),OR(AD14="D-K",AD14="D-R",AD14="DN-K",AD14="DN-R")),AND(OR(AC14="N-K",AC14="N-R"),OR(AD14="DN-K",AD14="DN-R"))),1,0) + IF(OR(AND(OR(AD14="DN-K",AD14="DN-R"),OR(AE14="D-K",AE14="D-R",AE14="DN-K",AE14="DN-R")),AND(OR(AD14="N-K",AD14="N-R"),OR(AE14="DN-K",AE14="DN-R"))),1,0) + IF(OR(AND(OR(AE14="DN-K",AE14="DN-R"),OR(AF14="D-K",AF14="D-R",AF14="DN-K",AF14="DN-R")),AND(OR(AE14="N-K",AE14="N-R"),OR(AF14="DN-K",AF14="DN-R"))),1,0))>0,"KONFLIKT 36H","OK") -> OK
A16: Obsada D | C16: =COUNTIF(C5:C14,"D-K")+COUNTIF(C5:C14,"D-R")+COUNTIF(C5:C14,"DN-K")+COUNTIF(C5:C14,"DN-R") -> 2 | D16: =COUNTIF(D5:D14,"D-K")+COUNTIF(D5:D14,"D-R")+COUNTIF(D5:D14,"DN-K")+COUNTIF(D5:D14,"DN-R") -> 2 | E16: =COUNTIF(E5:E14,"D-K")+COUNTIF(E5:E14,"D-R")+COUNTIF(E5:E14,"DN-K")+COUNTIF(E5:E14,"DN-R") -> 2 | F16: =COUNTIF(F5:F14,"D-K")+COUNTIF(F5:F14,"D-R")+COUNTIF(F5:F14,"DN-K")+COUNTIF(F5:F14,"DN-R") -> 2 | G16: =COUNTIF(G5:G14,"D-K")+COUNTIF(G5:G14,"D-R")+COUNTIF(G5:G14,"DN-K")+COUNTIF(G5:G14,"DN-R") -> 2 | H16: =COUNTIF(H5:H14,"D-K")+COUNTIF(H5:H14,"D-R")+COUNTIF(H5:H14,"DN-K")+COUNTIF(H5:H14,"DN-R") -> 2 | I16: =COUNTIF(I5:I14,"D-K")+COUNTIF(I5:I14,"D-R")+COUNTIF(I5:I14,"DN-K")+COUNTIF(I5:I14,"DN-R") -> 2 | J16: =COUNTIF(J5:J14,"D-K")+COUNTIF(J5:J14,"D-R")+COUNTIF(J5:J14,"DN-K")+COUNTIF(J5:J14,"DN-R") -> 2 | ... AF16: =COUNTIF(AF5:AF14,"D-K")+COUNTIF(AF5:AF14,"D-R")+COUNTIF(AF5:AF14,"DN-K")+COUNTIF(AF5:AF14,"DN-R") -> 2
A17: Obsada N | C17: =COUNTIF(C5:C14,"N-K")+COUNTIF(C5:C14,"N-R")+COUNTIF(C5:C14,"DN-K")+COUNTIF(C5:C14,"DN-R") -> 2 | D17: =COUNTIF(D5:D14,"N-K")+COUNTIF(D5:D14,"N-R")+COUNTIF(D5:D14,"DN-K")+COUNTIF(D5:D14,"DN-R") -> 2 | E17: =COUNTIF(E5:E14,"N-K")+COUNTIF(E5:E14,"N-R")+COUNTIF(E5:E14,"DN-K")+COUNTIF(E5:E14,"DN-R") -> 2 | F17: =COUNTIF(F5:F14,"N-K")+COUNTIF(F5:F14,"N-R")+COUNTIF(F5:F14,"DN-K")+COUNTIF(F5:F14,"DN-R") -> 2 | G17: =COUNTIF(G5:G14,"N-K")+COUNTIF(G5:G14,"N-R")+COUNTIF(G5:G14,"DN-K")+COUNTIF(G5:G14,"DN-R") -> 2 | H17: =COUNTIF(H5:H14,"N-K")+COUNTIF(H5:H14,"N-R")+COUNTIF(H5:H14,"DN-K")+COUNTIF(H5:H14,"DN-R") -> 2 | I17: =COUNTIF(I5:I14,"N-K")+COUNTIF(I5:I14,"N-R")+COUNTIF(I5:I14,"DN-K")+COUNTIF(I5:I14,"DN-R") -> 2 | J17: =COUNTIF(J5:J14,"N-K")+COUNTIF(J5:J14,"N-R")+COUNTIF(J5:J14,"DN-K")+COUNTIF(J5:J14,"DN-R") -> 2 | ... AF17: =COUNTIF(AF5:AF14,"N-K")+COUNTIF(AF5:AF14,"N-R")+COUNTIF(AF5:AF14,"DN-K")+COUNTIF(AF5:AF14,"DN-R") -> 2
A18: Brakuje D | C18: =MAX(0,Ustawienia!$E$4-C16) -> 0 | D18: =MAX(0,Ustawienia!$E$4-D16) -> 0 | E18: =MAX(0,Ustawienia!$E$4-E16) -> 0 | F18: =MAX(0,Ustawienia!$E$4-F16) -> 0 | G18: =MAX(0,Ustawienia!$E$4-G16) -> 0 | H18: =MAX(0,Ustawienia!$E$4-H16) -> 0 | I18: =MAX(0,Ustawienia!$E$4-I16) -> 0 | J18: =MAX(0,Ustawienia!$E$4-J16) -> 0 | ... AF18: =MAX(0,Ustawienia!$E$4-AF16) -> 0
A19: Brakuje N | C19: =MAX(0,Ustawienia!$E$5-C17) -> 0 | D19: =MAX(0,Ustawienia!$E$5-D17) -> 0 | E19: =MAX(0,Ustawienia!$E$5-E17) -> 0 | F19: =MAX(0,Ustawienia!$E$5-F17) -> 0 | G19: =MAX(0,Ustawienia!$E$5-G17) -> 0 | H19: =MAX(0,Ustawienia!$E$5-H17) -> 0 | I19: =MAX(0,Ustawienia!$E$5-I17) -> 0 | J19: =MAX(0,Ustawienia!$E$5-J17) -> 0 | ... AF19: =MAX(0,Ustawienia!$E$5-AF17) -> 0
A20: DYŻUR DO OBSADZENIA | C20: =IF(AND(C18>0,C19>0),"D/N",IF(C18>0,"D",IF(C19>0,"N",""))) | D20: =IF(AND(D18>0,D19>0),"D/N",IF(D18>0,"D",IF(D19>0,"N",""))) | E20: =IF(AND(E18>0,E19>0),"D/N",IF(E18>0,"D",IF(E19>0,"N",""))) | F20: =IF(AND(F18>0,F19>0),"D/N",IF(F18>0,"D",IF(F19>0,"N",""))) | G20: =IF(AND(G18>0,G19>0),"D/N",IF(G18>0,"D",IF(G19>0,"N",""))) | H20: =IF(AND(H18>0,H19>0),"D/N",IF(H18>0,"D",IF(H19>0,"N",""))) | I20: =IF(AND(I18>0,I19>0),"D/N",IF(I18>0,"D",IF(I19>0,"N",""))) | J20: =IF(AND(J18>0,J19>0),"D/N",IF(J18>0,"D",IF(J19>0,"N",""))) | ... AF20: =IF(AND(AF18>0,AF19>0),"D/N",IF(AF18>0,"D",IF(AF19>0,"N","")))
A25: PROPOZYCJE DYŻURÓW — wpisujesz tylko tutaj
A27: Lp | B27: Pracownik | C27: 1 | D27: 2 | E27: 3 | F27: 4 | G27: 5 | H27: 6 | I27: 7 | J27: 8 | K27: 9 | L27: 10 | M27: 11 | N27: 12 | O27: 13 | P27: 14 | Q27: 15 | R27: 16 | S27: 17 | T27: 18 | U27: 19 | V27: 20 | W27: 21 | X27: 22 | Y27: 23 | Z27: 24 | AA27: 25 | AB27: 26 | AC27: 27 | AD27: 28 | AE27: 29 | AF27: 30
C28: Wt | D28: Śr | E28: Cz | F28: Pt | G28: Sb | H28: Nd | I28: Pn | J28: Wt | K28: Śr | L28: Cz | M28: Pt | N28: Sb | O28: Nd | P28: Pn | Q28: Wt | R28: Śr | S28: Cz | T28: Pt | U28: Sb | V28: Nd | W28: Pn | X28: Wt | Y28: Śr | Z28: Cz | AA28: Pt | AB28: Sb | AC28: Nd | AD28: Pn | AE28: Wt | AF28: Śr
A29: 1 | B29: Reszczyński Łukasz | E29: DN-K | L29: DN-K | N29: DN-K | P29: N-K | S29: DN-K | Z29: DN-K | AB29: DN-K | AD29: DN-K
A30: 2 | B30: Ceplin Waldemar | F30: DN-R | G30: N-R | O30: DN-R | W30: DN-R | Y30: DN-K | AC30: DN-R
A31: 3 | B31: Martyna Paweł | D31: DN-K | G31: DN-K | L31: DN-R | O31: DN-K | AF31: DN-K
A32: 4 | B32: Michniewicz Tomasz | I32: DN-K | M32: DN-K | Q32: DN-R | U32: DN-K | AC32: DN-K
A33: 5 | B33: Porzeziński Mateusz | C33: DN-K | D33: N-R | F33: D-K | H33: DN-K | K33: DN-K | T33: DN-K | X33: DN-K | AA33: DN-K | AE33: N-R
A34: 6 | B34: Rogiński Tomasz | C34: D-R | F34: N-K | J34: DN-K | N34: D-R | R34: DN-K | V34: N-K | AE34: DN-K
A35: 7 | B35: Szaryński Tomasz | E35: DN-R | H35: DN-R | P35: DN-R | U35: DN-R | Y35: DN-R | AA35: DN-R
A36: 8 | B36: Szymański Tomasz | C36: N-R | D36: D-R | G36: D-R | I36: DN-R | K36: DN-R | N36: N-R | R36: D-R | S36: DN-R | V36: DN-R | AD36: D-R
A37: 9 | B37: Tekien Marek | P37: D-K | T37: DN-R | X37: DN-R | AB37: DN-R | AD37: N-R | AF37: DN-R
A38: 10 | B38: Turzyński Krystian | J38: DN-R | M38: DN-R | Q38: DN-K | R38: N-R | V38: D-K | W38: DN-K | Z38: DN-R | AE38: D-R
A43: Łącznie godzin / dzień | C43: =COUNTIF(C5:C14,"D-K")*12+COUNTIF(C5:C14,"D-R")*12+COUNTIF(C5:C14,"N-K")*12+COUNTIF(C5:C14,"N-R")*12+COUNTIF(C5:C14,"DN-K")*24+COUNTIF(C5:C14,"DN-R")*24 -> 48 | D43: =COUNTIF(D5:D14,"D-K")*12+COUNTIF(D5:D14,"D-R")*12+COUNTIF(D5:D14,"N-K")*12+COUNTIF(D5:D14,"N-R")*12+COUNTIF(D5:D14,"DN-K")*24+COUNTIF(D5:D14,"DN-R")*24 -> 48 | E43: =COUNTIF(E5:E14,"D-K")*12+COUNTIF(E5:E14,"D-R")*12+COUNTIF(E5:E14,"N-K")*12+COUNTIF(E5:E14,"N-R")*12+COUNTIF(E5:E14,"DN-K")*24+COUNTIF(E5:E14,"DN-R")*24 -> 48 | F43: =COUNTIF(F5:F14,"D-K")*12+COUNTIF(F5:F14,"D-R")*12+COUNTIF(F5:F14,"N-K")*12+COUNTIF(F5:F14,"N-R")*12+COUNTIF(F5:F14,"DN-K")*24+COUNTIF(F5:F14,"DN-R")*24 -> 48 | G43: =COUNTIF(G5:G14,"D-K")*12+COUNTIF(G5:G14,"D-R")*12+COUNTIF(G5:G14,"N-K")*12+COUNTIF(G5:G14,"N-R")*12+COUNTIF(G5:G14,"DN-K")*24+COUNTIF(G5:G14,"DN-R")*24 -> 48 | H43: =COUNTIF(H5:H14,"D-K")*12+COUNTIF(H5:H14,"D-R")*12+COUNTIF(H5:H14,"N-K")*12+COUNTIF(H5:H14,"N-R")*12+COUNTIF(H5:H14,"DN-K")*24+COUNTIF(H5:H14,"DN-R")*24 -> 48 | I43: =COUNTIF(I5:I14,"D-K")*12+COUNTIF(I5:I14,"D-R")*12+COUNTIF(I5:I14,"N-K")*12+COUNTIF(I5:I14,"N-R")*12+COUNTIF(I5:I14,"DN-K")*24+COUNTIF(I5:I14,"DN-R")*24 -> 48 | J43: =COUNTIF(J5:J14,"D-K")*12+COUNTIF(J5:J14,"D-R")*12+COUNTIF(J5:J14,"N-K")*12+COUNTIF(J5:J14,"N-R")*12+COUNTIF(J5:J14,"DN-K")*24+COUNTIF(J5:J14,"DN-R")*24 -> 48 | ... AF43: =COUNTIF(AF5:AF14,"D-K")*12+COUNTIF(AF5:AF14,"D-R")*12+COUNTIF(AF5:AF14,"N-K")*12+COUNTIF(AF5:AF14,"N-R")*12+COUNTIF(AF5:AF14,"DN-K")*24+COUNTIF(AF5:AF14,"DN-R")*24 -> 48
A44: Limit 48 h | C44: =IF(C43>48,"PRZEKROCZONE",IF(C43=48,"MAX","OK")) -> MAX | D44: =IF(D43>48,"PRZEKROCZONE",IF(D43=48,"MAX","OK")) -> MAX | E44: =IF(E43>48,"PRZEKROCZONE",IF(E43=48,"MAX","OK")) -> MAX | F44: =IF(F43>48,"PRZEKROCZONE",IF(F43=48,"MAX","OK")) -> MAX | G44: =IF(G43>48,"PRZEKROCZONE",IF(G43=48,"MAX","OK")) -> MAX | H44: =IF(H43>48,"PRZEKROCZONE",IF(H43=48,"MAX","OK")) -> MAX | I44: =IF(I43>48,"PRZEKROCZONE",IF(I43=48,"MAX","OK")) -> MAX | J44: =IF(J43>48,"PRZEKROCZONE",IF(J43=48,"MAX","OK")) -> MAX | ... AF44: =IF(AF43>48,"PRZEKROCZONE",IF(AF43=48,"MAX","OK")) -> MAX
A49: Kierowcy D | C49: =COUNTIF(C5:C14,"D-K")+COUNTIF(C5:C14,"DN-K") -> 1 | D49: =COUNTIF(D5:D14,"D-K")+COUNTIF(D5:D14,"DN-K") -> 1 | E49: =COUNTIF(E5:E14,"D-K")+COUNTIF(E5:E14,"DN-K") -> 1 | F49: =COUNTIF(F5:F14,"D-K")+COUNTIF(F5:F14,"DN-K") -> 1 | G49: =COUNTIF(G5:G14,"D-K")+COUNTIF(G5:G14,"DN-K") -> 1 | H49: =COUNTIF(H5:H14,"D-K")+COUNTIF(H5:H14,"DN-K") -> 1 | I49: =COUNTIF(I5:I14,"D-K")+COUNTIF(I5:I14,"DN-K") -> 1 | J49: =COUNTIF(J5:J14,"D-K")+COUNTIF(J5:J14,"DN-K") -> 1 | ... AF49: =COUNTIF(AF5:AF14,"D-K")+COUNTIF(AF5:AF14,"DN-K") -> 1
A50: Ratownicy D | C50: =COUNTIF(C5:C14,"D-R")+COUNTIF(C5:C14,"DN-R") -> 1 | D50: =COUNTIF(D5:D14,"D-R")+COUNTIF(D5:D14,"DN-R") -> 1 | E50: =COUNTIF(E5:E14,"D-R")+COUNTIF(E5:E14,"DN-R") -> 1 | F50: =COUNTIF(F5:F14,"D-R")+COUNTIF(F5:F14,"DN-R") -> 1 | G50: =COUNTIF(G5:G14,"D-R")+COUNTIF(G5:G14,"DN-R") -> 1 | H50: =COUNTIF(H5:H14,"D-R")+COUNTIF(H5:H14,"DN-R") -> 1 | I50: =COUNTIF(I5:I14,"D-R")+COUNTIF(I5:I14,"DN-R") -> 1 | J50: =COUNTIF(J5:J14,"D-R")+COUNTIF(J5:J14,"DN-R") -> 1 | ... AF50: =COUNTIF(AF5:AF14,"D-R")+COUNTIF(AF5:AF14,"DN-R") -> 1
A51: Kierowcy N | C51: =COUNTIF(C5:C14,"N-K")+COUNTIF(C5:C14,"DN-K") -> 1 | D51: =COUNTIF(D5:D14,"N-K")+COUNTIF(D5:D14,"DN-K") -> 1 | E51: =COUNTIF(E5:E14,"N-K")+COUNTIF(E5:E14,"DN-K") -> 1 | F51: =COUNTIF(F5:F14,"N-K")+COUNTIF(F5:F14,"DN-K") -> 1 | G51: =COUNTIF(G5:G14,"N-K")+COUNTIF(G5:G14,"DN-K") -> 1 | H51: =COUNTIF(H5:H14,"N-K")+COUNTIF(H5:H14,"DN-K") -> 1 | I51: =COUNTIF(I5:I14,"N-K")+COUNTIF(I5:I14,"DN-K") -> 1 | J51: =COUNTIF(J5:J14,"N-K")+COUNTIF(J5:J14,"DN-K") -> 1 | ... AF51: =COUNTIF(AF5:AF14,"N-K")+COUNTIF(AF5:AF14,"DN-K") -> 1
A52: Ratownicy N | C52: =COUNTIF(C5:C14,"N-R")+COUNTIF(C5:C14,"DN-R") -> 1 | D52: =COUNTIF(D5:D14,"N-R")+COUNTIF(D5:D14,"DN-R") -> 1 | E52: =COUNTIF(E5:E14,"N-R")+COUNTIF(E5:E14,"DN-R") -> 1 | F52: =COUNTIF(F5:F14,"N-R")+COUNTIF(F5:F14,"DN-R") -> 1 | G52: =COUNTIF(G5:G14,"N-R")+COUNTIF(G5:G14,"DN-R") -> 1 | H52: =COUNTIF(H5:H14,"N-R")+COUNTIF(H5:H14,"DN-R") -> 1 | I52: =COUNTIF(I5:I14,"N-R")+COUNTIF(I5:I14,"DN-R") -> 1 | J52: =COUNTIF(J5:J14,"N-R")+COUNTIF(J5:J14,"DN-R") -> 1 | ... AF52: =COUNTIF(AF5:AF14,"N-R")+COUNTIF(AF5:AF14,"DN-R") -> 1
A53: STATUS FUNKCJI | C53: =IF(AND(C49>=Ustawienia!$E$8,C50>=Ustawienia!$E$9,C51>=Ustawienia!$E$8,C52>=Ustawienia!$E$9),"OK","BRAK") -> OK | D53: =IF(AND(D49>=Ustawienia!$E$8,D50>=Ustawienia!$E$9,D51>=Ustawienia!$E$8,D52>=Ustawienia!$E$9),"OK","BRAK") -> OK | E53: =IF(AND(E49>=Ustawienia!$E$8,E50>=Ustawienia!$E$9,E51>=Ustawienia!$E$8,E52>=Ustawienia!$E$9),"OK","BRAK") -> OK | F53: =IF(AND(F49>=Ustawienia!$E$8,F50>=Ustawienia!$E$9,F51>=Ustawienia!$E$8,F52>=Ustawienia!$E$9),"OK","BRAK") -> OK | G53: =IF(AND(G49>=Ustawienia!$E$8,G50>=Ustawienia!$E$9,G51>=Ustawienia!$E$8,G52>=Ustawienia!$E$9),"OK","BRAK") -> OK | H53: =IF(AND(H49>=Ustawienia!$E$8,H50>=Ustawienia!$E$9,H51>=Ustawienia!$E$8,H52>=Ustawienia!$E$9),"OK","BRAK") -> OK | I53: =IF(AND(I49>=Ustawienia!$E$8,I50>=Ustawienia!$E$9,I51>=Ustawienia!$E$8,I52>=Ustawienia!$E$9),"OK","BRAK") -> OK | J53: =IF(AND(J49>=Ustawienia!$E$8,J50>=Ustawienia!$E$9,J51>=Ustawienia!$E$8,J52>=Ustawienia!$E$9),"OK","BRAK") -> OK | ... AF53: =IF(AND(AF49>=Ustawienia!$E$8,AF50>=Ustawienia!$E$9,AF51>=Ustawienia!$E$8,AF52>=Ustawienia!$E$9),"OK","BRAK") -> OK

Sheet Ustawienia
A1: USTAWIENIA GRAFIKU
A3: Kod | B3: Liczba godzin | D3: Minimalna obsada | E3: Liczba osób
A4: D | B4: 12 | D4: D | E4: 2
A5: N | B5: 12 | D5: N | E5: 2
A6: DN | B6: 24
A7: XX | B7: 0 | D7: Minimalna obsada wg funkcji | E7: Liczba
D8: Kierowca / zmiana | E8: 1
A9: Jak korzystać | D9: Ratownik / zmiana | E9: 1
A10: 1. | B10: W arkuszu „Grafik” wybieraj kod z listy: D / N / DN / XX.
A11: 2. | B11: Godziny zliczają się automatycznie, a różnica do kontraktu pokazuje nadmiar lub niedobór.
A12: 3. | B12: Zielone puste pola wskazują dni, w których brakuje obsady i można rozważyć dodatkowy dyżur.

Sheet Grafik finalny
A1: GRAFIK G01042 — WRZESIEŃ 2026
A3: Lp | B3: Pracownik | C3: 1 | D3: 2 | E3: 3 | F3: 4 | G3: 5 | H3: 6 | I3: 7 | J3: 8 | K3: 9 | L3: 10 | M3: 11 | N3: 12 | O3: 13 | P3: 14 | Q3: 15 | R3: 16 | S3: 17 | T3: 18 | U3: 19 | V3: 20 | W3: 21 | X3: 22 | Y3: 23 | Z3: 24 | AA3: 25 | AB3: 26 | AC3: 27 | AD3: 28 | AE3: 29 | AF3: 30 | AG3: Wypracowane godziny | AH3: Min h | AI3: Max h | AJ3: Status | AK3: Kontrola 36 h
